Workbook

Sheet merged_clean
A1: Product | B1: Machine | C1: Level | D1: Time normal (min) | E1: Time mastered (min) | F1: Time in hayday.info (min) | G1: hayday.info time basis | H1: Sell price | I1: Sell price (Fandom, if different) | J1: XP | K1: XP (Fandom, if different) | L1: Profit/hr (site) | M1: XP/hr (site) | N1: Flag | O1: Found in | P1: Status | Q1: Conflict fields | R1: Source | S1: Fandom page
A2: Egg | B2: Animal Products | C2: 1 | F2: 20 | G2: =IF(OR(F2="",AND(D2="",E2="")),"n/a",IF(F2=E2,"mastered",IF(F2=D2,"normal","differs"))) -> n/a | H2: 18 | J2: 2 | L2: 33 | M2: 6 | N2: =IF(L2="","",IF(L2<0,"negative profit",IF(L2>Notes!$B$4,"unusually high - verify",""))) | O2: hayday.info | P2: =IF(O2<>"both",O2&" only",IF(Q2="","agree","conflict")) -> hayday.info only | Q2: =IF(O2="both",TRIM(IF(I2<>"","price ","")&IF(K2<>"","xp ","")&IF(G2="differs","time","")),"") | R2: hayday.info /api/production-data only
A3: Milk | B3: Animal Products | C3: 6 | F3: 60 | G3: =IF(OR(F3="",AND(D3="",E3="")),"n/a",IF(F3=E3,"mastered",IF(F3=D3,"normal","differs"))) -> n/a | H3: 32 | J3: 3 | L3: 18 | M3: 3 | N3: =IF(L3="","",IF(L3<0,"negative profit",IF(L3>Notes!$B$4,"unusually high - verify",""))) | O3: hayday.info | P3: =IF(O3<>"both",O3&" only",IF(Q3="","agree","conflict")) -> hayday.info only | Q3: =IF(O3="both",TRIM(IF(I3<>"","price ","")&IF(K3<>"","xp ","")&IF(G3="differs","time","")),"") | R3: hayday.info /api/production-data only
A4: Bacon | B4: Animal Products | C4: 10 | F4: 240 | G4: =IF(OR(F4="",AND(D4="",E4="")),"n/a",IF(F4=E4,"mastered",IF(F4=D4,"normal","differs"))) -> n/a | H4: 50 | J4: 5 | L4: -2.5 | M4: 1.25 | N4: =IF(L4="","",IF(L4<0,"negative profit",IF(L4>Notes!$B$4,"unusually high - verify",""))) -> negative profit | O4: hayday.info | P4: =IF(O4<>"both",O4&" only",IF(Q4="","agree","conflict")) -> hayday.info only | Q4: =IF(O4="both",TRIM(IF(I4<>"","price ","")&IF(K4<>"","xp ","")&IF(G4="differs","time","")),"") | R4: hayday.info /api/production-data only
A5: Wool | B5: Animal Products | C5: 16 | F5: 360 | G5: =IF(OR(F5="",AND(D5="",E5="")),"n/a",IF(F5=E5,"mastered",IF(F5=D5,"normal","differs"))) -> n/a | H5: 54 | J5: 5 | L5: -0.83333333 | M5: 0.83333333 | N5: =IF(L5="","",IF(L5<0,"negative profit",IF(L5>Notes!$B$4,"unusually high - verify",""))) -> negative profit | O5: hayday.info | P5: =IF(O5<>"both",O5&" only",IF(Q5="","agree","conflict")) -> hayday.info only | Q5: =IF(O5="both",TRIM(IF(I5<>"","price ","")&IF(K5<>"","xp ","")&IF(G5="differs","time","")),"") | R5: hayday.info /api/production-data only
A6: Goat Milk | B6: Animal Products | C6: 32 | F6: 480 | G6: =IF(OR(F6="",AND(D6="",E6="")),"n/a",IF(F6=E6,"mastered",IF(F6=D6,"normal","differs"))) -> n/a | H6: 64 | J6: 6 | L6: -1.25 | M6: 0.75 | N6: =IF(L6="","",IF(L6<0,"negative profit",IF(L6>Notes!$B$4,"unusually high - verify",""))) -> negative profit | O6: hayday.info | P6: =IF(O6<>"both",O6&" only",IF(Q6="","agree","conflict")) -> hayday.info only | Q6: =IF(O6="both",TRIM(IF(I6<>"","price ","")&IF(K6<>"","xp ","")&IF(G6="differs","time","")),"") | R6: hayday.info /api/production-data only
A7: Bread | B7: Bakery | C7: 2 | D7: 5 | E7: 4 | F7: 4 | G7: =IF(OR(F7="",AND(D7="",E7="")),"n/a",IF(F7=E7,"mastered",IF(F7=D7,"normal","differs"))) -> mastered | H7: 21 | J7: 3 | L7: 169.41176 | M7: 42.352941 | N7: =IF(L7="","",IF(L7<0,"negative profit",IF(L7>Notes!$B$4,"unusually high - verify",""))) | O7: both | P7: =IF(O7<>"both",O7&" only",IF(Q7="","agree","conflict")) -> agree | Q7: =IF(O7="both",TRIM(IF(I7<>"","price ","")&IF(K7<>"","xp ","")&IF(G7="differs","time","")),"") | R7: hayday.info (primary values) + Fandom (times, cross-check) | S7: https://hayday.fandom.com/wiki/Bakery
A8: Corn Bread | B8: Bakery | C8: 7 | D8: 30 | E8: 25 | F8: 25 | G8: =IF(OR(F8="",AND(D8="",E8="")),"n/a",IF(F8=E8,"mastered",IF(F8=D8,"normal","differs"))) -> mastered | H8: 72 | J8: 8 | L8: 51.764706 | M8: 18.823529 | N8: =IF(L8="","",IF(L8<0,"negative profit",IF(L8>Notes!$B$4,"unusually high - verify",""))) | O8: both | P8: =IF(O8<>"both",O8&" only",IF(Q8="","agree","conflict")) -> agree | Q8: =IF(O8="both",TRIM(IF(I8<>"","price ","")&IF(K8<>"","xp ","")&IF(G8="differs","time","")),"") | R8: hayday.info (primary values) + Fandom (times, cross-check) | S8: https://hayday.fandom.com/wiki/Bakery
A9: Cookie | B9: Bakery | C9: 10 | D9: 60 | E9: 51 | F9: 51 | G9: =IF(OR(F9="",AND(D9="",E9="")),"n/a",IF(F9=E9,"mastered",IF(F9=D9,"normal","differs"))) -> mastered | H9: 104 | J9: 13 | L9: 35.294118 | M9: 15.294118 | N9: =IF(L9="","",IF(L9<0,"negative profit",IF(L9>Notes!$B$4,"unusually high - verify",""))) | O9: both | P9: =IF(O9<>"both",O9&" only",IF(Q9="","agree","conflict")) -> agree | Q9: =IF(O9="both",TRIM(IF(I9<>"","price ","")&IF(K9<>"","xp ","")&IF(G9="differs","time","")),"") | R9: hayday.info (primary values) + Fandom (times, cross-check) | S9: https://hayday.fandom.com/wiki/Bakery
A10: Raspberry Muffin | B10: Bakery | C10: 19 | D10: 45 | E10: 38 | F10: 38 | G10: =IF(OR(F10="",AND(D10="",E10="")),"n/a",IF(F10=E10,"mastered",IF(F10=D10,"normal","differs"))) -> mastered | H10: 140 | J10: 17 | L10: 37.647059 | M10: 26.666667 | N10: =IF(L10="","",IF(L10<0,"negative profit",IF(L10>Notes!$B$4,"unusually high - verify",""))) | O10: both | P10: =IF(O10<>"both",O10&" only",IF(Q10="","agree","conflict")) -> agree | Q10: =IF(O10="both",TRIM(IF(I10<>"","price ","")&IF(K10<>"","xp ","")&IF(G10="differs","time","")),"") | R10: hayday.info (primary values) + Fandom (times, cross-check) | S10: https://hayday.fandom.com/wiki/Bakery
A11: Blackberry Muffin | B11: Bakery | C11: 26 | D11: 45 | E11: 38 | F11: 38 | G11: =IF(OR(F11="",AND(D11="",E11="")),"n/a",IF(F11=E11,"mastered",IF(F11=D11,"normal","differs"))) -> mastered | H11: 226 | J11: 27 | L11: 36.078431 | M11: 42.352941 | N11: =IF(L11="","",IF(L11<0,"negative profit",IF(L11>Notes!$B$4,"unusually high - verify",""))) | O11: both | P11: =IF(O11<>"both",O11&" only",IF(Q11="","agree","conflict")) -> agree | Q11: =IF(O11="both",TRIM(IF(I11<>"","price ","")&IF(K11<>"","xp ","")&IF(G11="differs","time","")),"") | R11: hayday.info (primary values) + Fandom (times, cross-check) | S11: https://hayday.fandom.com/wiki/Bakery
A12: Pizza | B12: Bakery | C12: 33 | D12: 15 | E12: 12 | F12: 12 | G12: =IF(OR(F12="",AND(D12="",E12="")),"n/a",IF(F12=E12,"mastered",IF(F12=D12,"normal","differs"))) -> mastered | H12: 190 | J12: 23 | L12: 89.411765 | M12: 108.23529 | N12: =IF(L12="","",IF(L12<0,"negative profit",IF(L12>Notes!$B$4,"unusually high - verify",""))) | O12: both | P12: =IF(O12<>"both",O12&" only",IF(Q12="","agree","conflict")) -> agree | Q12: =IF(O12="both",TRIM(IF(I12<>"","price ","")&IF(K12<>"","xp ","")&IF(G12="differs","time","")),"") | R12: hayday.info (primary values) + Fandom (times, cross-check) | S12: https://hayday.fandom.com/wiki/Bakery
A13: Spicy Pizza | B13: Bakery | C13: 37 | D13: 15 | E13: 12 | F13: 12 | G13: =IF(OR(F13="",AND(D13="",E13="")),"n/a",IF(F13=E13,"mastered",IF(F13=D13,"normal","differs"))) -> mastered | H13: 226 | J13: 27 | L13: 89.411765 | M13: 127.05882 | N13: =IF(L13="","",IF(L13<0,"negative profit",IF(L13>Notes!$B$4,"unusually high - verify",""))) | O13: both | P13: =IF(O13<>"both",O13&" only",IF(Q13="","agree","conflict")) -> agree | Q13: =IF(O13="both",TRIM(IF(I13<>"","price ","")&IF(K13<>"","xp ","")&IF(G13="differs","time","")),"") | R13: hayday.info (primary values) + Fandom (times, cross-check) | S13: https://hayday.fandom.com/wiki/Bakery
A14: Potato Bread | B14: Bakery | C14: 39 | D14: 45 | E14: 38 | F14: 38 | G14: =IF(OR(F14="",AND(D14="",E14="")),"n/a",IF(F14=E14,"mastered",IF(F14=D14,"normal","differs"))) -> mastered | H14: 284 | J14: 34 | L14: 40.784314 | M14: 53.333333 | N14: =IF(L14="","",IF(L14<0,"negative profit",IF(L14>Notes!$B$4,"unusually high - verify",""))) | O14: both | P14: =IF(O14<>"both",O14&" only",IF(Q14="","agree","conflict")) -> agree | Q14: =IF(O14="both",TRIM(IF(I14<>"","price ","")&IF(K14<>"","xp ","")&IF(G14="differs","time","")),"") | R14: hayday.info (primary values) + Fandom (times, cross-check) | S14: https://hayday.fandom.com/wiki/Bakery
A15: Frutti di Mare Pizza | B15: Bakery | C15: 45 | F15: 12 | G15: =IF(OR(F15="",AND(D15="",E15="")),"n/a",IF(F15=E15,"mastered",IF(F15=D15,"normal","differs"))) -> n/a | H15: 403 | J15: 48 | L15: 94.117647 | M15: 225.88235 | N15: =IF(L15="","",IF(L15<0,"negative profit",IF(L15>Notes!$B$4,"unusually high - verify",""))) | O15: hayday.info | P15: =IF(O15<>"both",O15&" only",IF(Q15="","agree","conflict")) -> hayday.info only | Q15: =IF(O15="both",TRIM(IF(I15<>"","price ","")&IF(K15<>"","xp ","")&IF(G15="differs","time","")),"") | R15: hayday.info /api/production-data only
A16: Gingerbread Cookie | B16: Bakery | C16: 86 | F16: 25 | G16: =IF(OR(F16="",AND(D16="",E16="")),"n/a",IF(F16=E16,"mastered",IF(F16=D16,"normal","differs"))) -> n/a | H16: 273 | J16: 33 | L16: 70.588235 | M16: 77.647059 | N16: =IF(L16="","",IF(L16<0,"negative profit",IF(L16>Notes!$B$4,"unusually high - verify",""))) | O16: hayday.info | P16: =IF(O16<>"both",O16&" only",IF(Q16="","agree","conflict")) -> hayday.info only | Q16: =IF(O16="both",TRIM(IF(I16<>"","price ","")&IF(K16<>"","xp ","")&IF(G16="differs","time","")),"") | R16: hayday.info /api/production-data only
A17: Banana Bread | B17: Bakery | C17: 91 | F17: 25 | G17: =IF(OR(F17="",AND(D17="",E17="")),"n/a",IF(F17=E17,"mastered",IF(F17=D17,"normal","differs"))) -> n/a | H17: 424 | J17: 50 | L17: 49.411765 | M17: 117.64706 | N17: =IF(L17="","",IF(L17<0,"negative profit",IF(L17>Notes!$B$4,"unusually high - verify",""))) | O17: hayday.info | P17: =IF(O17<>"both",O17&" only",IF(Q17="","agree","conflict")) -> hayday.info only | Q17: =IF(O17="both",TRIM(IF(I17<>"","price ","")&IF(K17<>"","xp ","")&IF(G17="differs","time","")),"") | R17: hayday.info /api/production-data only
A18: Macaroon | B18: Bakery | C18: 101 | F18: 30 | G18: =IF(OR(F18="",AND(D18="",E18="")),"n/a",IF(F18=E18,"mastered",IF(F18=D18,"normal","differs"))) -> n/a | H18: 421 | J18: 50 | L18: 38 | M18: 100 | N18: =IF(L18="","",IF(L18<0,"negative profit",IF(L18>Notes!$B$4,"unusually high - verify",""))) | O18: hayday.info | P18: =IF(O18<>"both",O18&" only",IF(Q18="","agree","conflict")) -> hayday.info only | Q18: =IF(O18="both",TRIM(IF(I18<>"","price ","")&IF(K18<>"","xp ","")&IF(G18="differs","time","")),"") | R18: hayday.info /api/production-data only
A19: Honey Soap | B19: Bath Kiosk | C19: 84 | F19: 51 | G19: =IF(OR(F19="",AND(D19="",E19="")),"n/a",IF(F19=E19,"mastered",IF(F19=D19,"normal","differs"))) -> n/a | H19: 327 | J19: 39 | L19: 27.058824 | M19: 45.882353 | N19: =IF(L19="","",IF(L19<0,"negative profit",IF(L19>Notes!$B$4,"unusually high - verify",""))) | O19: hayday.info | P19: =IF(O19<>"both",O19&" only",IF(Q19="","agree","conflict")) -> hayday.info only | Q19: =IF(O19="both",TRIM(IF(I19<>"","price ","")&IF(K19<>"","xp ","")&IF(G19="differs","time","")),"") | R19: hayday.info /api/production-data only
A20: Lemon Lotion | B20: Bath Kiosk | C20: 84 | F20: 63 | G20: =IF(OR(F20="",AND(D20="",E20="")),"n/a",IF(F20=E20,"mastered",IF(F20=D20,"normal","differs"))) -> n/a | H20: 403 | J20: 48 | L20: 31.058824 | M20: 45.176471 | N20: =IF(L20="","",IF(L20<0,"negative profit",IF(L20>Notes!$B$4,"unusually high - verify",""))) | O20: hayday.info | P20: =IF(O20<>"both",O20&" only",IF(Q20="","agree","conflict")) -> hayday.info only | Q20: =IF(O20="both",TRIM(IF(I20<>"","price ","")&IF(K20<>"","xp ","")&IF(G20="differs","time","")),"") | R20: hayday.info /api/production-data only
A21: Exfoliating Soap | B21: Bath Kiosk | C21: 93 | F21: 51 | G21: =IF(OR(F21="",AND(D21="",E21="")),"n/a",IF(F21=E21,"mastered",IF(F21=D21,"normal","differs"))) -> n/a | H21: 363 | J21: 43 | L21: 20 | M21: 50.588235 | N21: =IF(L21="","",IF(L21<0,"negative profit",IF(L21>Notes!$B$4,"unusually high - verify",""))) | O21: hayday.info | P21: =IF(O21<>"both",O21&" only",IF(Q21="","agree","conflict")) -> hayday.info only | Q21: =IF(O21="both",TRIM(IF(I21<>"","price ","")&IF(K21<>"","xp ","")&IF(G21="differs","time","")),"") | R21: hayday.info /api/production-data only
A22: Honey Face Mask | B22: Bath Kiosk | C22: 99 | F22: 76 | G22: =IF(OR(F22="",AND(D22="",E22="")),"n/a",IF(F22=E22,"mastered",IF(F22=D22,"normal","differs"))) -> n/a | H22: 320 | J22: 38 | L22: 29.019608 | M22: 29.803922 | N22: =IF(L22="","",IF(L22<0,"negative profit",IF(L22>Notes!$B$4,"unusually high - verify",""))) | O22: hayday.info | P22: =IF(O22<>"both",O22&" only",IF(Q22="","agree","conflict")) -> hayday.info only | Q22: =IF(O22="both",TRIM(IF(I22<>"","price ","")&IF(K22<>"","xp ","")&IF(G22="differs","time","")),"") | R22: hayday.info /api/production-data only
A23: Pancake | B23: BBQ Grill | C23: 9 | F23: 25 | G23: =IF(OR(F23="",AND(D23="",E23="")),"n/a",IF(F23=E23,"mastered",IF(F23=D23,"normal","differs"))) -> n/a | H23: 108 | J23: 13 | L23: 51.764706 | M23: 30.588235 | N23: =IF(L23="","",IF(L23<0,"negative profit",IF(L23>Notes!$B$4,"unusually high - verify",""))) | O23: hayday.info | P23: =IF(O23<>"both",O23&" only",IF(Q23="","agree","conflict")) -> hayday.info only | Q23: =IF(O23="both",TRIM(IF(I23<>"","price ","")&IF(K23<>"","xp ","")&IF(G23="differs","time","")),"") | R23: hayday.info /api/production-data only
A24: Bacon and Eggs | B24: BBQ Grill | C24: 11 | F24: 51 | G24: =IF(OR(F24="",AND(D24="",E24="")),"n/a",IF(F24=E24,"mastered",IF(F24=D24,"normal","differs"))) -> n/a | H24: 201 | J24: 24 | L24: 34.117647 | M24: 28.235294 | N24: =IF(L24="","",IF(L24<0,"negative profit",IF(L24>Notes!$B$4,"unusually high - verify",""))) | O24: hayday.info | P24: =IF(O24<>"both",O24&" only",IF(Q24="","agree","conflict")) -> hayday.info only | Q24: =IF(O24="both",TRIM(IF(I24<>"","price ","")&IF(K24<>"","xp ","")&IF(G24="differs","time","")),"") | R24: hayday.info /api/production-data only
A25: Hamburger | B25: BBQ Grill | C25: 18 | F25: 102 | G25: =IF(OR(F25="",AND(D25="",E25="")),"n/a",IF(F25=E25,"mastered",IF(F25=D25,"normal","differs"))) -> n/a | H25: 180 | J25: 22 | L25: 22.352941 | M25: 12.941176 | N25: =IF(L25="","",IF(L25<0,"negative profit",IF(L25>Notes!$B$4,"unusually high - verify",""))) | O25: hayday.info | P25: =IF(O25<>"both",O25&" only",IF(Q25="","agree","conflict")) -> hayday.info only | Q25: =IF(O25="both",TRIM(IF(I25<>"","price ","")&IF(K25<>"","xp ","")&IF(G25="differs","time","")),"") | R25: hayday.info /api/production-data only
A26: Fish Burger | B26: BBQ Grill | C26: 27 | F26: 102 | G26: =IF(OR(F26="",AND(D26="",E26="")),"n/a",IF(F26=E26,"mastered",IF(F26=D26,"normal","differs"))) -> n/a | H26: 226 | J26: 27 | L26: 23.529412 | M26: 15.882353 | N26: =IF(L26="","",IF(L26<0,"negative profit",IF(L26>Notes!$B$4,"unusually high - verify",""))) | O26: hayday.info | P26: =IF(O26<>"both",O26&" only",IF(Q26="","agree","conflict")) -> hayday.info only | Q26: =IF(O26="both",TRIM(IF(I26<>"","price ","")&IF(K26<>"","xp ","")&IF(G26="differs","time","")),"") | R26: hayday.info /api/production-data only
... A37: Fish Skewer | B37: BBQ Grill | C37: 96 | F37: 25 | G37: =IF(OR(F37="",AND(D37="",E37="")),"n/a",IF(F37=E37,"mastered",IF(F37=D37,"normal","differs"))) -> n/a | H37: 176 | J37: 21 | L37: 65.882353 | M37: 49.411765 | N37: =IF(L37="","",IF(L37<0,"negative profit",IF(L37>Notes!$B$4,"unusually high - verify",""))) | O37: hayday.info | P37: =IF(O37<>"both",O37&" only",IF(Q37="","agree","conflict")) -> hayday.info only | Q37: =IF(O37="both",TRIM(IF(I37<>"","price ","")&IF(K37<>"","xp ","")&IF(G37="differs","time","")),"") | R37: hayday.info /api/production-data only
A38: Carrot Cake | B38: Cake Oven | C38: 21 | D38: 90 | E38: 76 | F38: 76 | G38: =IF(OR(F38="",AND(D38="",E38="")),"n/a",IF(F38=E38,"mastered",IF(F38=D38,"normal","differs"))) -> mastered | H38: 165 | J38: 20 | L38: 29.019608 | M38: 15.686275 | N38: =IF(L38="","",IF(L38<0,"negative profit",IF(L38>Notes!$B$4,"unusually high - verify",""))) | O38: both | P38: =IF(O38<>"both",O38&" only",IF(Q38="","agree","conflict")) -> agree | Q38: =IF(O38="both",TRIM(IF(I38<>"","price ","")&IF(K38<>"","xp ","")&IF(G38="differs","time","")),"") | R38: hayday.info (primary values) + Fandom (times, cross-check) | S38: https://hayday.fandom.com/wiki/Cake_Oven
A39: Cream Cake | B39: Cake Oven | C39: 23 | D39: 180 | E39: 153 | F39: 153 | G39: =IF(OR(F39="",AND(D39="",E39="")),"n/a",IF(F39=E39,"mastered",IF(F39=D39,"normal","differs"))) -> mastered | H39: 219 | J39: 26 | L39: 40.784314 | M39: 10.196078 | N39: =IF(L39="","",IF(L39<0,"negative profit",IF(L39>Notes!$B$4,"unusually high - verify",""))) | O39: both | P39: =IF(O39<>"both",O39&" only",IF(Q39="","agree","conflict")) -> agree | Q39: =IF(O39="both",TRIM(IF(I39<>"","price ","")&IF(K39<>"","xp ","")&IF(G39="differs","time","")),"") | R39: hayday.info (primary values) + Fandom (times, cross-check) | S39: https://hayday.fandom.com/wiki/Cake_Oven
A40: Red Berry Cake | B40: Cake Oven | C40: 23 | D40: 60 | E40: 51 | F40: 51 | G40: =IF(OR(F40="",AND(D40="",E40="")),"n/a",IF(F40=E40,"mastered",IF(F40=D40,"normal","differs"))) -> mastered | H40: 255 | J40: 31 | L40: 27.058824 | M40: 36.470588 | N40: =IF(L40="","",IF(L40<0,"negative profit",IF(L40>Notes!$B$4,"unusually high - verify",""))) | O40: both | P40: =IF(O40<>"both",O40&" only",IF(Q40="","agree","conflict")) -> agree | Q40: =IF(O40="both",TRIM(IF(I40<>"","price ","")&IF(K40<>"","xp ","")&IF(G40="differs","time","")),"") | R40: hayday.info (primary values) + Fandom (times, cross-check) | S40: https://hayday.fandom.com/wiki/Cake_Oven
A41: Cheesecake | B41: Cake Oven | C41: 24 | D41: 240 | E41: 204 | F41: 204 | G41: =IF(OR(F41="",AND(D41="",E41="")),"n/a",IF(F41=E41,"mastered",IF(F41=D41,"normal","differs"))) -> mastered | H41: 284 | J41: 34 | L41: 17.058824 | M41: 10 | N41: =IF(L41="","",IF(L41<0,"negative profit",IF(L41>Notes!$B$4,"unusually high - verify",""))) | O41: both | P41: =IF(O41<>"both",O41&" only",IF(Q41="","agree","conflict")) -> agree | Q41: =IF(O41="both",TRIM(IF(I41<>"","price ","")&IF(K41<>"","xp ","")&IF(G41="differs","time","")),"") | R41: hayday.info (primary values) + Fandom (times, cross-check) | S41: https://hayday.fandom.com/wiki/Cake_Oven
A42: Strawberry Cake | B42: Cake Oven | C42: 35 | D42: 180 | E42: 153 | F42: 153 | G42: =IF(OR(F42="",AND(D42="",E42="")),"n/a",IF(F42=E42,"mastered",IF(F42=D42,"normal","differs"))) -> mastered | H42: 316 | J42: 38 | L42: 41.960784 | M42: 14.901961 | N42: =IF(L42="","",IF(L42<0,"negative profit",IF(L42>Notes!$B$4,"unusually high - verify",""))) | O42: both | P42: =IF(O42<>"both",O42&" only",IF(Q42="","agree","conflict")) -> agree | Q42: =IF(O42="both",TRIM(IF(I42<>"","price ","")&IF(K42<>"","xp ","")&IF(G42="differs","time","")),"") | R42: hayday.info (primary values) + Fandom (times, cross-check) | S42: https://hayday.fandom.com/wiki/Cake_Oven
A43: Chocolate Cake | B43: Cake Oven | C43: 36 | D43: 120 | E43: 102 | F43: 102 | G43: =IF(OR(F43="",AND(D43="",E43="")),"n/a",IF(F43=E43,"mastered",IF(F43=D43,"normal","differs"))) -> mastered | H43: 320 | J43: 38 | L43: 20 | M43: 22.352941 | N43: =IF(L43="","",IF(L43<0,"negative profit",IF(L43>Notes!$B$4,"unusually high - verify",""))) | O43: both | P43: =IF(O43<>"both",O43&" only",IF(Q43="","agree","conflict")) -> agree | Q43: =IF(O43="both",TRIM(IF(I43<>"","price ","")&IF(K43<>"","xp ","")&IF(G43="differs","time","")),"") | R43: hayday.info (primary values) + Fandom (times, cross-check) | S43: https://hayday.fandom.com/wiki/Cake_Oven
A44: Potato Feta Cake | B44: Cake Oven | C44: 38 | D44: 120 | E44: 102 | F44: 102 | G44: =IF(OR(F44="",AND(D44="",E44="")),"n/a",IF(F44=E44,"mastered",IF(F44=D44,"normal","differs"))) -> mastered | H44: 309 | J44: 37 | L44: 22.941176 | M44: 21.764706 | N44: =IF(L44="","",IF(L44<0,"negative profit",IF(L44>Notes!$B$4,"unusually high - verify",""))) | O44: both | P44: =IF(O44<>"both",O44&" only",IF(Q44="","agree","conflict")) -> agree | Q44: =IF(O44="both",TRIM(IF(I44<>"","price ","")&IF(K44<>"","xp ","")&IF(G44="differs","time","")),"") | R44: hayday.info (primary values) + Fandom (times, cross-check) | S44: https://hayday.fandom.com/wiki/Cake_Oven
A45: Honey Apple Cake | B45: Cake Oven | C45: 42 | D45: 200 | E45: 170 | F45: 170 | G45: =IF(OR(F45="",AND(D45="",E45="")),"n/a",IF(F45=E45,"mastered",IF(F45=D45,"normal","differs"))) -> mastered | H45: 482 | J45: 57 | L45: 19.058824 | M45: 20.117647 | N45: =IF(L45="","",IF(L45<0,"negative profit",IF(L45>Notes!$B$4,"unusually high - verify",""))) | O45: both | P45: =IF(O45<>"both",O45&" only",IF(Q45="","agree","conflict")) -> agree | Q45: =IF(O45="both",TRIM(IF(I45<>"","price ","")&IF(K45<>"","xp ","")&IF(G45="differs","time","")),"") | R45: hayday.info (primary values) + Fandom (times, cross-check) | S45: https://hayday.fandom.com/wiki/Cake_Oven
A46: Fancy Cake | B46: Cake Oven | C46: 54 | D46: 15 | E46: 12 | F46: 12 | G46: =IF(OR(F46="",AND(D46="",E46="")),"n/a",IF(F46=E46,"mastered",IF(F46=D46,"normal","differs"))) -> mastered | H46: 450 | J46: 49 | L46: 42.352941 | M46: 230.58824 | N46: =IF(L46="","",IF(L46<0,"negative profit",IF(L46>Notes!$B$4,"unusually high - verify",""))) | O46: both | P46: =IF(O46<>"both",O46&" only",IF(Q46="","agree","conflict")) -> agree | Q46: =IF(O46="both",TRIM(IF(I46<>"","price ","")&IF(K46<>"","xp ","")&IF(G46="differs","time","")),"") | R46: hayday.info (primary values) + Fandom (times, cross-check) | S46: https://hayday.fandom.com/wiki/Cake_Oven
A47: Pineapple Cake | B47: Cake Oven | C47: 65 | D47: 75 | E47: 63 | F47: 63 | G47: =IF(OR(F47="",AND(D47="",E47="")),"n/a",IF(F47=E47,"mastered",IF(F47=D47,"normal","differs"))) -> mastered | H47: 259 | J47: 31 | L47: 31.058824 | M47: 29.176471 | N47: =IF(L47="","",IF(L47<0,"negative profit",IF(L47>Notes!$B$4,"unusually high - verify",""))) | O47: both | P47: =IF(O47<>"both",O47&" only",IF(Q47="","agree","conflict")) -> agree | Q47: =IF(O47="both",TRIM(IF(I47<>"","price ","")&IF(K47<>"","xp ","")&IF(G47="differs","time","")),"") | R47: hayday.info (primary values) + Fandom (times, cross-check) | S47: https://hayday.fandom.com/wiki/Cake_Oven
A48: Lemon Cake | B48: Cake Oven | C48: 68 | D48: 150 | E48: 127 | F48: 127 | G48: =IF(OR(F48="",AND(D48="",E48="")),"n/a",IF(F48=E48,"mastered",IF(F48=D48,"normal","differs"))) -> mastered | H48: 896 | J48: 107 | L48: 21.176471 | M48: 50.352941 | N48: =IF(L48="","",IF(L48<0,"negative profit",IF(L48>Notes!$B$4,"unusually high - verify",""))) | O48: both | P48: =IF(O48<>"both",O48&" only",IF(Q48="","agree","conflict")) -> agree | Q48: =IF(O48="both",TRIM(IF(I48<>"","price ","")&IF(K48<>"","xp ","")&IF(G48="differs","time","")),"") | R48: hayday.info (primary values) + Fandom (times, cross-check) | S48: https://hayday.fandom.com/wiki/Cake_Oven
A49: Fruit Cake | B49: Cake Oven | C49: 89 | D49: 180 | E49: 153 | F49: 153 | G49: =IF(OR(F49="",AND(D49="",E49="")),"n/a",IF(F49=E49,"mastered",IF(F49=D49,"normal","differs"))) -> mastered | H49: 450 | J49: 54 | L49: 18.431373 | M49: 21.176471 | N49: =IF(L49="","",IF(L49<0,"negative profit",IF(L49>Notes!$B$4,"unusually high - verify",""))) | O49: both | P49: =IF(O49<>"both",O49&" only",IF(Q49="","agree","conflict")) -> agree | Q49: =IF(O49="both",TRIM(IF(I49<>"","price ","")&IF(K49<>"","xp ","")&IF(G49="differs","time","")),"") | R49: hayday.info (primary values) + Fandom (times, cross-check) | S49: https://hayday.fandom.com/wiki/Cake_Oven
A50: Chocolate Roll | B50: Cake Oven | C50: 95 | F50: 76 | G50: =IF(OR(F50="",AND(D50="",E50="")),"n/a",IF(F50=E50,"mastered",IF(F50=D50,"normal","differs"))) -> n/a | H50: 604 | J50: 72 | L50: 14.901961 | M50: 56.470588 | N50: =IF(L50="","",IF(L50<0,"negative profit",IF(L50>Notes!$B$4,"unusually high - verify",""))) | O50: hayday.info | P50: =IF(O50<>"both",O50&" only",IF(Q50="","agree","conflict")) -> hayday.info only | Q50: =IF(O50="both",TRIM(IF(I50<>"","price ","")&IF(K50<>"","xp ","")&IF(G50="differs","time","")),"") | R50: hayday.info /api/production-data only
...

Sheet hayday_info
A1: Product | B1: Machine | C1: Level | D1: Time (min) | E1: Sell price | F1: XP | G1: Profit/hr (site) | H1: XP/hr (site) | I1: Flag | J1: Source
A2: Egg | B2: Animal Products | C2: 1 | D2: 20 | E2: 18 | F2: 2 | G2: 33 | H2: 6 | I2: =IF(G2<0,"negative profit",IF(G2>Notes!$B$4,"unusually high - verify","")) | J2: hayday.info /api/production-data (https://hayday.info/api/production-data)
A3: Milk | B3: Animal Products | C3: 6 | D3: 60 | E3: 32 | F3: 3 | G3: 18 | H3: 3 | I3: =IF(G3<0,"negative profit",IF(G3>Notes!$B$4,"unusually high - verify","")) | J3: hayday.info /api/production-data (https://hayday.info/api/production-data)
A4: Bacon | B4: Animal Products | C4: 10 | D4: 240 | E4: 50 | F4: 5 | G4: -2.5 | H4: 1.25 | I4: =IF(G4<0,"negative profit",IF(G4>Notes!$B$4,"unusually high - verify","")) -> negative profit | J4: hayday.info /api/production-data (https://hayday.info/api/production-data)
A5: Wool | B5: Animal Products | C5: 16 | D5: 360 | E5: 54 | F5: 5 | G5: -0.83333333 | H5: 0.83333333 | I5: =IF(G5<0,"negative profit",IF(G5>Notes!$B$4,"unusually high - verify","")) -> negative profit | J5: hayday.info /api/production-data (https://hayday.info/api/production-data)
A6: Goat milk | B6: Animal Products | C6: 32 | D6: 480 | E6: 64 | F6: 6 | G6: -1.25 | H6: 0.75 | I6: =IF(G6<0,"negative profit",IF(G6>Notes!$B$4,"unusually high - verify","")) -> negative profit | J6: hayday.info /api/production-data (https://hayday.info/api/production-data)
A7: Bread | B7: Bakery | C7: 2 | D7: 4 | E7: 21 | F7: 3 | G7: 169.41176 | H7: 42.352941 | I7: =IF(G7<0,"negative profit",IF(G7>Notes!$B$4,"unusually high - verify","")) | J7: hayday.info /api/production-data (https://hayday.info/api/production-data)
A8: Corn bread | B8: Bakery | C8: 7 | D8: 25 | E8: 72 | F8: 8 | G8: 51.764706 | H8: 18.823529 | I8: =IF(G8<0,"negative profit",IF(G8>Notes!$B$4,"unusually high - verify","")) | J8: hayday.info /api/production-data (https://hayday.info/api/production-data)
A9: Cookie | B9: Bakery | C9: 10 | D9: 51 | E9: 104 | F9: 13 | G9: 35.294118 | H9: 15.294118 | I9: =IF(G9<0,"negative profit",IF(G9>Notes!$B$4,"unusually high - verify","")) | J9: hayday.info /api/production-data (https://hayday.info/api/production-data)
A10: Raspberry muffin | B10: Bakery | C10: 19 | D10: 38 | E10: 140 | F10: 17 | G10: 37.647059 | H10: 26.666667 | I10: =IF(G10<0,"negative profit",IF(G10>Notes!$B$4,"unusually high - verify","")) | J10: hayday.info /api/production-data (https://hayday.info/api/production-data)
A11: Blackberry muffin | B11: Bakery | C11: 26 | D11: 38 | E11: 226 | F11: 27 | G11: 36.078431 | H11: 42.352941 | I11: =IF(G11<0,"negative profit",IF(G11>Notes!$B$4,"unusually high - verify","")) | J11: hayday.info /api/production-data (https://hayday.info/api/production-data)
A12: Pizza | B12: Bakery | C12: 33 | D12: 12 | E12: 190 | F12: 23 | G12: 89.411765 | H12: 108.23529 | I12: =IF(G12<0,"negative profit",IF(G12>Notes!$B$4,"unusually high - verify","")) | J12: hayday.info /api/production-data (https://hayday.info/api/production-data)
A13: Spicy pizza | B13: Bakery | C13: 37 | D13: 12 | E13: 226 | F13: 27 | G13: 89.411765 | H13: 127.05882 | I13: =IF(G13<0,"negative profit",IF(G13>Notes!$B$4,"unusually high - verify","")) | J13: hayday.info /api/production-data (https://hayday.info/api/production-data)
... A349: Tropical Yogurt | B349: Yogurt Maker | C349: 109 | D349: 51 | E349: 457 | F349: 54 | G349: -210.58824 | H349: 63.529412 | I349: =IF(G349<0,"negative profit",IF(G349>Notes!$B$4,"unusually high - verify","")) -> negative profit | J349: hayday.info /api/production-data (https://hayday.info/api/production-data)

Sheet fandom_all
A1: Product | B1: Machine | C1: Level | D1: Time normal (min) | E1: Time mastered (min) | F1: Sell price | G1: XP | H1: Note | I1: Source | J1: hayday.info time | K1: Time check | L1: hayday.info price | M1: Price check | N1: hayday.info XP | O1: XP check | P1: Level check
A2: Bread | B2: Bakery | C2: 2 | D2: 5 | E2: 4 | F2: 21 | G2: 3 | I2: Hay Day Wiki (Fandom) https://hayday.fandom.com/wiki/Bakery | J2: =IFERROR(INDEX(hayday_info!$D$2:$D$349,MATCH($A2,hayday_info!$A$2:$A$349,0)),"not found") -> 4 | K2: =IF(J2="not found","not in hayday.info",IF(J2=E2,"matches mastered",IF(J2=D2,"matches normal","differs"))) -> matches mastered | L2: =IFERROR(INDEX(hayday_info!$E$2:$E$349,MATCH($A2,hayday_info!$A$2:$A$349,0)),"not found") -> 21 | M2: =IF(L2="not found","not in hayday.info",IF(F2="","no Fandom value",IF(L2=F2,"match","differs"))) -> match | N2: =IFERROR(INDEX(hayday_info!$F$2:$F$349,MATCH($A2,hayday_info!$A$2:$A$349,0)),"not found") -> 3 | O2: =IF(N2="not found","not in hayday.info",IF(G2="","no Fandom value",IF(N2=G2,"match","differs"))) -> match | P2: =IF(J2="not found","not in hayday.info",IF(C2="","no Fandom value",IF(IFERROR(INDEX(hayday_info!$C$2:$C$349,MATCH($A2,hayday_info!$A$2:$A$349,0)),"not found")=C2,"match","differs"))) -> match
A3: Corn Bread | B3: Bakery | C3: 7 | D3: 30 | E3: 25 | F3: 72 | G3: 8 | I3: Hay Day Wiki (Fandom) https://hayday.fandom.com/wiki/Bakery | J3: =IFERROR(INDEX(hayday_info!$D$2:$D$349,MATCH($A3,hayday_info!$A$2:$A$349,0)),"not found") -> 25 | K3: =IF(J3="not found","not in hayday.info",IF(J3=E3,"matches mastered",IF(J3=D3,"matches normal","differs"))) -> matches mastered | L3: =IFERROR(INDEX(hayday_info!$E$2:$E$349,MATCH($A3,hayday_info!$A$2:$A$349,0)),"not found") -> 72 | M3: =IF(L3="not found","not in hayday.info",IF(F3="","no Fandom value",IF(L3=F3,"match","differs"))) -> match | N3: =IFERROR(INDEX(hayday_info!$F$2:$F$349,MATCH($A3,hayday_info!$A$2:$A$349,0)),"not found") -> 8 | O3: =IF(N3="not found","not in hayday.info",IF(G3="","no Fandom value",IF(N3=G3,"match","differs"))) -> match | P3: =IF(J3="not found","not in hayday.info",IF(C3="","no Fandom value",IF(IFERROR(INDEX(hayday_info!$C$2:$C$349,MATCH($A3,hayday_info!$A$2:$A$349,0)),"not found")=C3,"match","differs"))) -> match
A4: Cookie | B4: Bakery | C4: 10 | D4: 60 | E4: 51 | F4: 104 | G4: 13 | I4: Hay Day Wiki (Fandom) https://hayday.fandom.com/wiki/Bakery | J4: =IFERROR(INDEX(hayday_info!$D$2:$D$349,MATCH($A4,hayday_info!$A$2:$A$349,0)),"not found") -> 51 | K4: =IF(J4="not found","not in hayday.info",IF(J4=E4,"matches mastered",IF(J4=D4,"matches normal","differs"))) -> matches mastered | L4: =IFERROR(INDEX(hayday_info!$E$2:$E$349,MATCH($A4,hayday_info!$A$2:$A$349,0)),"not found") -> 104 | M4: =IF(L4="not found","not in hayday.info",IF(F4="","no Fandom value",IF(L4=F4,"match","differs"))) -> match | N4: =IFERROR(INDEX(hayday_info!$F$2:$F$349,MATCH($A4,hayday_info!$A$2:$A$349,0)),"not found") -> 13 | O4: =IF(N4="not found","not in hayday.info",IF(G4="","no Fandom value",IF(N4=G4,"match","differs"))) -> match | P4: =IF(J4="not found","not in hayday.info",IF(C4="","no Fandom value",IF(IFERROR(INDEX(hayday_info!$C$2:$C$349,MATCH($A4,hayday_info!$A$2:$A$349,0)),"not found")=C4,"match","differs"))) -> match
A5: Raspberry Muffin | B5: Bakery | C5: 19 | D5: 45 | E5: 38 | F5: 140 | G5: 17 | I5: Hay Day Wiki (Fandom) https://hayday.fandom.com/wiki/Bakery | J5: =IFERROR(INDEX(hayday_info!$D$2:$D$349,MATCH($A5,hayday_info!$A$2:$A$349,0)),"not found") -> 38 | K5: =IF(J5="not found","not in hayday.info",IF(J5=E5,"matches mastered",IF(J5=D5,"matches normal","differs"))) -> matches mastered | L5: =IFERROR(INDEX(hayday_info!$E$2:$E$349,MATCH($A5,hayday_info!$A$2:$A$349,0)),"not found") -> 140 | M5: =IF(L5="not found","not in hayday.info",IF(F5="","no Fandom value",IF(L5=F5,"match","differs"))) -> match | N5: =IFERROR(INDEX(hayday_info!$F$2:$F$349,MATCH($A5,hayday_info!$A$2:$A$349,0)),"not found") -> 17 | O5: =IF(N5="not found","not in hayday.info",IF(G5="","no Fandom value",IF(N5=G5,"match","differs"))) -> match | P5: =IF(J5="not found","not in hayday.info",IF(C5="","no Fandom value",IF(IFERROR(INDEX(hayday_info!$C$2:$C$349,MATCH($A5,hayday_info!$A$2:$A$349,0)),"not found")=C5,"match","differs"))) -> match
A6: Blackberry Muffin | B6: Bakery | C6: 26 | D6: 45 | E6: 38 | F6: 226 | G6: 27 | I6: Hay Day Wiki (Fandom) https://hayday.fandom.com/wiki/Bakery | J6: =IFERROR(INDEX(hayday_info!$D$2:$D$349,MATCH($A6,hayday_info!$A$2:$A$349,0)),"not found") -> 38 | K6: =IF(J6="not found","not in hayday.info",IF(J6=E6,"matches mastered",IF(J6=D6,"matches normal","differs"))) -> matches mastered | L6: =IFERROR(INDEX(hayday_info!$E$2:$E$349,MATCH($A6,hayday_info!$A$2:$A$349,0)),"not found") -> 226 | M6: =IF(L6="not found","not in hayday.info",IF(F6="","no Fandom value",IF(L6=F6,"match","differs"))) -> match | N6: =IFERROR(INDEX(hayday_info!$F$2:$F$349,MATCH($A6,hayday_info!$A$2:$A$349,0)),"not found") -> 27 | O6: =IF(N6="not found","not in hayday.info",IF(G6="","no Fandom value",IF(N6=G6,"match","differs"))) -> match | P6: =IF(J6="not found","not in hayday.info",IF(C6="","no Fandom value",IF(IFERROR(INDEX(hayday_info!$C$2:$C$349,MATCH($A6,hayday_info!$A$2:$A$349,0)),"not found")=C6,"match","differs"))) -> match
A7: Pizza | B7: Bakery | C7: 33 | D7: 15 | E7: 12 | F7: 190 | G7: 23 | I7: Hay Day Wiki (Fandom) https://hayday.fandom.com/wiki/Bakery | J7: =IFERROR(INDEX(hayday_info!$D$2:$D$349,MATCH($A7,hayday_info!$A$2:$A$349,0)),"not found") -> 12 | K7: =IF(J7="not found","not in hayday.info",IF(J7=E7,"matches mastered",IF(J7=D7,"matches normal","differs"))) -> matches mastered | L7: =IFERROR(INDEX(hayday_info!$E$2:$E$349,MATCH($A7,hayday_info!$A$2:$A$349,0)),"not found") -> 190 | M7: =IF(L7="not found","not in hayday.info",IF(F7="","no Fandom value",IF(L7=F7,"match","differs"))) -> match | N7: =IFERROR(INDEX(hayday_info!$F$2:$F$349,MATCH($A7,hayday_info!$A$2:$A$349,0)),"not found") -> 23 | O7: =IF(N7="not found","not in hayday.info",IF(G7="","no Fandom value",IF(N7=G7,"match","differs"))) -> match | P7: =IF(J7="not found","not in hayday.info",IF(C7="","no Fandom value",IF(IFERROR(INDEX(hayday_info!$C$2:$C$349,MATCH($A7,hayday_info!$A$2:$A$349,0)),"not found")=C7,"match","differs"))) -> match
A8: Spicy Pizza | B8: Bakery | C8: 37 | D8: 15 | E8: 12 | F8: 226 | G8: 27 | I8: Hay Day Wiki (Fandom) https://hayday.fandom.com/wiki/Bakery | J8: =IFERROR(INDEX(hayday_info!$D$2:$D$349,MATCH($A8,hayday_info!$A$2:$A$349,0)),"not found") -> 12 | K8: =IF(J8="not found","not in hayday.info",IF(J8=E8,"matches mastered",IF(J8=D8,"matches normal","differs"))) -> matches mastered | L8: =IFERROR(INDEX(hayday_info!$E$2:$E$349,MATCH($A8,hayday_info!$A$2:$A$349,0)),"not found") -> 226 | M8: =IF(L8="not found","not in hayday.info",IF(F8="","no Fandom value",IF(L8=F8,"match","differs"))) -> match | N8: =IFERROR(INDEX(hayday_info!$F$2:$F$349,MATCH($A8,hayday_info!$A$2:$A$349,0)),"not found") -> 27 | O8: =IF(N8="not found","not in hayday.info",IF(G8="","no Fandom value",IF(N8=G8,"match","differs"))) -> match | P8: =IF(J8="not found","not in hayday.info",IF(C8="","no Fandom value",IF(IFERROR(INDEX(hayday_info!$C$2:$C$349,MATCH($A8,hayday_info!$A$2:$A$349,0)),"not found")=C8,"match","differs"))) -> match
A9: Potato Bread | B9: Bakery | C9: 39 | D9: 45 | E9: 38 | F9: 284 | G9: 34 | I9: Hay Day Wiki (Fandom) https://hayday.fandom.com/wiki/Bakery | J9: =IFERROR(INDEX(hayday_info!$D$2:$D$349,MATCH($A9,hayday_info!$A$2:$A$349,0)),"not found") -> 38 | K9: =IF(J9="not found","not in hayday.info",IF(J9=E9,"matches mastered",IF(J9=D9,"matches normal","differs"))) -> matches mastered | L9: =IFERROR(INDEX(hayday_info!$E$2:$E$349,MATCH($A9,hayday_info!$A$2:$A$349,0)),"not found") -> 284 | M9: =IF(L9="not found","not in hayday.info",IF(F9="","no Fandom value",IF(L9=F9,"match","differs"))) -> match | N9: =IFERROR(INDEX(hayday_info!$F$2:$F$349,MATCH($A9,hayday_info!$A$2:$A$349,0)),"not found") -> 34 | O9: =IF(N9="not found","not in hayday.info",IF(G9="","no Fandom value",IF(N9=G9,"match","differs"))) -> match | P9: =IF(J9="not found","not in hayday.info",IF(C9="","no Fandom value",IF(IFERROR(INDEX(hayday_info!$C$2:$C$349,MATCH($A9,hayday_info!$A$2:$A$349,0)),"not found")=C9,"match","differs"))) -> match
A10: Cream | B10: Dairy | C10: 6 | D10: 20 | E10: 17 | F10: 50 | G10: 6 | I10: Hay Day Wiki (Fandom) https://hayday.fandom.com/wiki/Dairy | J10: =IFERROR(INDEX(hayday_info!$D$2:$D$349,MATCH($A10,hayday_info!$A$2:$A$349,0)),"not found") -> 17 | K10: =IF(J10="not found","not in hayday.info",IF(J10=E10,"matches mastered",IF(J10=D10,"matches normal","differs"))) -> matches mastered | L10: =IFERROR(INDEX(hayday_info!$E$2:$E$349,MATCH($A10,hayday_info!$A$2:$A$349,0)),"not found") -> 50 | M10: =IF(L10="not found","not in hayday.info",IF(F10="","no Fandom value",IF(L10=F10,"match","differs"))) -> match | N10: =IFERROR(INDEX(hayday_info!$F$2:$F$349,MATCH($A10,hayday_info!$A$2:$A$349,0)),"not found") -> 6 | O10: =IF(N10="not found","not in hayday.info",IF(G10="","no Fandom value",IF(N10=G10,"match","differs"))) -> match | P10: =IF(J10="not found","not in hayday.info",IF(C10="","no Fandom value",IF(IFERROR(INDEX(hayday_info!$C$2:$C$349,MATCH($A10,hayday_info!$A$2:$A$349,0)),"not found")=C10,"match","differs"))) -> match
A11: Butter | B11: Dairy | C11: 9 | D11: 30 | E11: 25 | F11: 82 | G11: 10 | I11: Hay Day Wiki (Fandom) https://hayday.fandom.com/wiki/Dairy | J11: =IFERROR(INDEX(hayday_info!$D$2:$D$349,MATCH($A11,hayday_info!$A$2:$A$349,0)),"not found") -> 25 | K11: =IF(J11="not found","not in hayday.info",IF(J11=E11,"matches mastered",IF(J11=D11,"matches normal","differs"))) -> matches mastered | L11: =IFERROR(INDEX(hayday_info!$E$2:$E$349,MATCH($A11,hayday_info!$A$2:$A$349,0)),"not found") -> 82 | M11: =IF(L11="not found","not in hayday.info",IF(F11="","no Fandom value",IF(L11=F11,"match","differs"))) -> match | N11: =IFERROR(INDEX(hayday_info!$F$2:$F$349,MATCH($A11,hayday_info!$A$2:$A$349,0)),"not found") -> 10 | O11: =IF(N11="not found","not in hayday.info",IF(G11="","no Fandom value",IF(N11=G11,"match","differs"))) -> match | P11: =IF(J11="not found","not in hayday.info",IF(C11="","no Fandom value",IF(IFERROR(INDEX(hayday_info!$C$2:$C$349,MATCH($A11,hayday_info!$A$2:$A$349,0)),"not found")=C11,"match","differs"))) -> match
A12: Cheese | B12: Dairy | C12: 12 | D12: 60 | E12: 51 | F12: 122 | G12: 15 | I12: Hay Day Wiki (Fandom) https://hayday.fandom.com/wiki/Dairy | J12: =IFERROR(INDEX(hayday_info!$D$2:$D$349,MATCH($A12,hayday_info!$A$2:$A$349,0)),"not found") -> 51 | K12: =IF(J12="not found","not in hayday.info",IF(J12=E12,"matches mastered",IF(J12=D12,"matches normal","differs"))) -> matches mastered | L12: =IFERROR(INDEX(hayday_info!$E$2:$E$349,MATCH($A12,hayday_info!$A$2:$A$349,0)),"not found") -> 122 | M12: =IF(L12="not found","not in hayday.info",IF(F12="","no Fandom value",IF(L12=F12,"match","differs"))) -> match | N12: =IFERROR(INDEX(hayday_info!$F$2:$F$349,MATCH($A12,hayday_info!$A$2:$A$349,0)),"not found") -> 15 | O12: =IF(N12="not found","not in hayday.info",IF(G12="","no Fandom value",IF(N12=G12,"match","differs"))) -> match | P12: =IF(J12="not found","not in hayday.info",IF(C12="","no Fandom value",IF(IFERROR(INDEX(hayday_info!$C$2:$C$349,MATCH($A12,hayday_info!$A$2:$A$349,0)),"not found")=C12,"match","differs"))) -> match
A13: Goat Cheese | B13: Dairy | C13: 33 | D13: 90 | E13: 76 | F13: 162 | G13: 19 | I13: Hay Day Wiki (Fandom) https://hayday.fandom.com/wiki/Dairy | J13: =IFERROR(INDEX(hayday_info!$D$2:$D$349,MATCH($A13,hayday_info!$A$2:$A$349,0)),"not found") -> 76 | K13: =IF(J13="not found","not in hayday.info",IF(J13=E13,"matches mastered",IF(J13=D13,"matches normal","differs"))) -> matches mastered | L13: =IFERROR(INDEX(hayday_info!$E$2:$E$349,MATCH($A13,hayday_info!$A$2:$A$349,0)),"not found") -> 162 | M13: =IF(L13="not found","not in hayday.info",IF(F13="","no Fandom value",IF(L13=F13,"match","differs"))) -> match | N13: =IFERROR(INDEX(hayday_info!$F$2:$F$349,MATCH($A13,hayday_info!$A$2:$A$349,0)),"not found") -> 19 | O13: =IF(N13="not found","not in hayday.info",IF(G13="","no Fandom value",IF(N13=G13,"match","differs"))) -> match | P13: =IF(J13="not found","not in hayday.info",IF(C13="","no Fandom value",IF(IFERROR(INDEX(hayday_info!$C$2:$C$349,MATCH($A13,hayday_info!$A$2:$A$349,0)),"not found")=C13,"match","differs"))) -> match
... A49: Goat feed | B49: Feed Mill | C49: 32 | D49: 40 | E49: 34 | F49: 14 | G49: 3 | I49: Hay Day Wiki (Fandom) https://hayday.fandom.com/wiki/Feed_Mill | J49: =IFERROR(INDEX(hayday_info!$D$2:$D$349,MATCH($A49,hayday_info!$A$2:$A$349,0)),"not found") -> 34 | K49: =IF(J49="not found","not in hayday.info",IF(J49=E49,"matches mastered",IF(J49=D49,"matches normal","differs"))) -> matches mastered | L49: =IFERROR(INDEX(hayday_info!$E$2:$E$349,MATCH($A49,hayday_info!$A$2:$A$349,0)),"not found") -> 14 | M49: =IF(L49="not found","not in hayday.info",IF(F49="","no Fandom value",IF(L49=F49,"match","differs"))) -> match | N49: =IFERROR(INDEX(hayday_info!$F$2:$F$349,MATCH($A49,hayday_info!$A$2:$A$349,0)),"not found") -> 3 | O49: =IF(N49="not found","not in hayday.info",IF(G49="","no Fandom value",IF(N49=G49,"match","differs"))) -> match | P49: =IF(J49="not found","not in hayday.info",IF(C49="","no Fandom value",IF(IFERROR(INDEX(hayday_info!$C$2:$C$349,MATCH($A49,hayday_info!$A$2:$A$349,0)),"not found")=C49,"match","differs"))) -> match
A50: Wheat Bundle | B50: Feed Mill | D50: 85 | E50: 76 | F50: 50 | G50: 10 | H50: Level shown on page as 'Rep 3' (reputation requirement), left blank | I50: Hay Day Wiki (Fandom) https://hayday.fandom.com/wiki/Feed_Mill | J50: =IFERROR(INDEX(hayday_info!$D$2:$D$349,MATCH($A50,hayday_info!$A$2:$A$349,0)),"not found") -> 76 | K50: =IF(J50="not found","not in hayday.info",IF(J50=E50,"matches mastered",IF(J50=D50,"matches normal","differs"))) -> matches mastered | L50: =IFERROR(INDEX(hayday_info!$E$2:$E$349,MATCH($A50,hayday_info!$A$2:$A$349,0)),"not found") -> 50 | M50: =IF(L50="not found","not in hayday.info",IF(F50="","no Fandom value",IF(L50=F50,"match","differs"))) -> match | N50: =IFERROR(INDEX(hayday_info!$F$2:$F$349,MATCH($A50,hayday_info!$A$2:$A$349,0)),"not found") -> 10 | O50: =IF(N50="not found","not in hayday.info",IF(G50="","no Fandom value",IF(N50=G50,"match","differs"))) -> match | P50: =IF(J50="not found","not in hayday.info",IF(C50="","no Fandom value",IF(IFERROR(INDEX(hayday_info!$C$2:$C$349,MATCH($A50,hayday_info!$A$2:$A$349,0)),"not found")=C50,"match","differs"))) -> no Fandom value
A51: Sweater | B51: Loom | C51: 17 | D51: 120 | E51: 102 | F51: 151 | G51: 18 | I51: Hay Day Wiki (Fandom) https://hayday.fandom.com/wiki/Loom | J51: =IFERROR(INDEX(hayday_info!$D$2:$D$349,MATCH($A51,hayday_info!$A$2:$A$349,0)),"not found") -> 102 | K51: =IF(J51="not found","not in hayday.info",IF(J51=E51,"matches mastered",IF(J51=D51,"matches normal","differs"))) -> matches mastered | L51: =IFERROR(INDEX(hayday_info!$E$2:$E$349,MATCH($A51,hayday_info!$A$2:$A$349,0)),"not found") -> 151 | M51: =IF(L51="not found","not in hayday.info",IF(F51="","no Fandom value",IF(L51=F51,"match","differs"))) -> match | N51: =IFERROR(INDEX(hayday_info!$F$2:$F$349,MATCH($A51,hayday_info!$A$2:$A$349,0)),"not found") -> 18 | O51: =IF(N51="not found","not in hayday.info",IF(G51="","no Fandom value",IF(N51=G51,"match","differs"))) -> match | P51: =IF(J51="not found","not in hayday.info",IF(C51="","no Fandom value",IF(IFERROR(INDEX(hayday_info!$C$2:$C$349,MATCH($A51,hayday_info!$A$2:$A$349,0)),"not found")=C51,"match","differs"))) -> match
A52: Cotton fabric | B52: Loom | C52: 18 | D52: 30 | E52: 25 | F52: 108 | G52: 13 | I52: Hay Day Wiki (Fandom) https://hayday.fandom.com/wiki/Loom | J52: =IFERROR(INDEX(hayday_info!$D$2:$D$349,MATCH($A52,hayday_info!$A$2:$A$349,0)),"not found") -> 25 | K52: =IF(J52="not found","not in hayday.info",IF(J52=E52,"matches mastered",IF(J52=D52,"matches normal","differs"))) -> matches mastered | L52: =IFERROR(INDEX(hayday_info!$E$2:$E$349,MATCH($A52,hayday_info!$A$2:$A$349,0)),"not found") -> 108 | M52: =IF(L52="not found","not in hayday.info",IF(F52="","no Fandom value",IF(L52=F52,"match","differs"))) -> match | N52: =IFERROR(INDEX(hayday_info!$F$2:$F$349,MATCH($A52,hayday_info!$A$2:$A$349,0)),"not found") -> 13 | O52: =IF(N52="not found","not in hayday.info",IF(G52="","no Fandom value",IF(N52=G52,"match","differs"))) -> match | P52: =IF(J52="not found","not in hayday.info",IF(C52="","no Fandom value",IF(IFERROR(INDEX(hayday_info!$C$2:$C$349,MATCH($A52,hayday_info!$A$2:$A$349,0)),"not found")=C52,"match","differs"))) -> match
A53: Blue woolly hat | B53: Loom | C53: 19 | D53: 60 | E53: 51 | F53: 111 | G53: 13 | I53: Hay Day Wiki (Fandom) https://hayday.fandom.com/wiki/Loom | J53: =IFERROR(INDEX(hayday_info!$D$2:$D$349,MATCH($A53,hayday_info!$A$2:$A$349,0)),"not found") -> 51 | K53: =IF(J53="not found","not in hayday.info",IF(J53=E53,"matches mastered",IF(J53=D53,"matches normal","differs"))) -> matches mastered | L53: =IFERROR(INDEX(hayday_info!$E$2:$E$349,MATCH($A53,hayday_info!$A$2:$A$349,0)),"not found") -> 111 | M53: =IF(L53="not found","not in hayday.info",IF(F53="","no Fandom value",IF(L53=F53,"match","differs"))) -> match | N53: =IFERROR(INDEX(hayday_info!$F$2:$F$349,MATCH($A53,hayday_info!$A$2:$A$349,0)),"not found") -> 13 | O53: =IF(N53="not found","not in hayday.info",IF(G53="","no Fandom value",IF(N53=G53,"match","differs"))) -> match | P53: =IF(J53="not found","not in hayday.info",IF(C53="","no Fandom value",IF(IFERROR(INDEX(hayday_info!$C$2:$C$349,MATCH($A53,hayday_info!$A$2:$A$349,0)),"not found")=C53,"match","differs"))) -> match
A54: Blue sweater | B54: Loom | C54: 20 | D54: 180 | E54: 153 | F54: 208 | G54: 25 | I54: Hay Day Wiki (Fandom) https://hayday.fandom.com/wiki/Loom | J54: =IFERROR(INDEX(hayday_info!$D$2:$D$349,MATCH($A54,hayday_info!$A$2:$A$349,0)),"not found") -> 153 | K54: =IF(J54="not found","not in hayday.info",IF(J54=E54,"matches mastered",IF(J54=D54,"matches normal","differs"))) -> matches mastered | L54: =IFERROR(INDEX(hayday_info!$E$2:$E$349,MATCH($A54,hayday_info!$A$2:$A$349,0)),"not found") -> 208 | M54: =IF(L54="not found","not in hayday.info",IF(F54="","no Fandom value",IF(L54=F54,"match","differs"))) -> match | N54: =IFERROR(INDEX(hayday_info!$F$2:$F$349,MATCH($A54,hayday_info!$A$2:$A$349,0)),"not found") -> 25 | O54: =IF(N54="not found","not in hayday.info",IF(G54="","no Fandom value",IF(N54=G54,"match","differs"))) -> match | P54: =IF(J54="not found","not in hayday.info",IF(C54="","no Fandom value",IF(IFERROR(INDEX(hayday_info!$C$2:$C$349,MATCH($A54,hayday_info!$A$2:$A$349,0)),"not found")=C54,"match","differs"))) -> match
A55: Red scarf | B55: Loom | C55: 48 | D55: 150 | E55: 127 | F55: 288 | G55: 34 | I55: Hay Day Wiki (Fandom) https://hayday.fandom.com/wiki/Loom | J55: =IFERROR(INDEX(hayday_info!$D$2:$D$349,MATCH($A55,hayday_info!$A$2:$A$349,0)),"not found") -> 127 | K55: =IF(J55="not found","not in hayday.info",IF(J55=E55,"matches mastered",IF(J55=D55,"matches normal","differs"))) -> matches mastered | L55: =IFERROR(INDEX(hayday_info!$E$2:$E$349,MATCH($A55,hayday_info!$A$2:$A$349,0)),"not found") -> 288 | M55: =IF(L55="not found","not in hayday.info",IF(F55="","no Fandom value",IF(L55=F55,"match","differs"))) -> match | N55: =IFERROR(INDEX(hayday_info!$F$2:$F$349,MATCH($A55,hayday_info!$A$2:$A$349,0)),"not found") -> 34 | O55: =IF(N55="not found","not in hayday.info",IF(G55="","no Fandom value",IF(N55=G55,"match","differs"))) -> match | P55: =IF(J55="not found","not in hayday.info",IF(C55="","no Fandom value",IF(IFERROR(INDEX(hayday_info!$C$2:$C$349,MATCH($A55,hayday_info!$A$2:$A$349,0)),"not found")=C55,"match","differs"))) -> match
A56: Flower shawl | B56: Loom | C56: 71 | D56: 90 | E56: 76 | F56: 295 | G56: 35 | I56: Hay Day Wiki (Fandom) https://hayday.fandom.com/wiki/Loom | J56: =IFERROR(INDEX(hayday_info!$D$2:$D$349,MATCH($A56,hayday_info!$A$2:$A$349,0)),"not found") -> 76 | K56: =IF(J56="not found","not in hayday.info",IF(J56=E56,"matches mastered",IF(J56=D56,"matches normal","differs"))) -> matches mastered | L56: =IFERROR(INDEX(hayday_info!$E$2:$E$349,MATCH($A56,hayday_info!$A$2:$A$349,0)),"not found") -> 295 | M56: =IF(L56="not found","not in hayday.info",IF(F56="","no Fandom value",IF(L56=F56,"match","differs"))) -> match | N56: =IFERROR(INDEX(hayday_info!$F$2:$F$349,MATCH($A56,hayday_info!$A$2:$A$349,0)),"not found") -> 35 | O56: =IF(N56="not found","not in hayday.info",IF(G56="","no Fandom value",IF(N56=G56,"match","differs"))) -> match | P56: =IF(J56="not found","not in hayday.info",IF(C56="","no Fandom value",IF(IFERROR(INDEX(hayday_info!$C$2:$C$349,MATCH($A56,hayday_info!$A$2:$A$349,0)),"not found")=C56,"match","differs"))) -> match
A57: Cotton Shirt | B57: Sewing Machine | C57: 19 | D57: 45 | E57: 38 | F57: 241 | G57: 29 | I57: Hay Day Wiki (Fandom) https://hayday.fandom.com/wiki/Sewing_Machine | J57: =IFERROR(INDEX(hayday_info!$D$2:$D$349,MATCH($A57,hayday_info!$A$2:$A$349,0)),"not found") -> 38 | K57: =IF(J57="not found","not in hayday.info",IF(J57=E57,"matches mastered",IF(J57=D57,"matches normal","differs"))) -> matches mastered | L57: =IFERROR(INDEX(hayday_info!$E$2:$E$349,MATCH($A57,hayday_info!$A$2:$A$349,0)),"not found") -> 241 | M57: =IF(L57="not found","not in hayday.info",IF(F57="","no Fandom value",IF(L57=F57,"match","differs"))) -> match | N57: =IFERROR(INDEX(hayday_info!$F$2:$F$349,MATCH($A57,hayday_info!$A$2:$A$349,0)),"not found") -> 29 | O57: =IF(N57="not found","not in hayday.info",IF(G57="","no Fandom value",IF(N57=G57,"match","differs"))) -> match | P57: =IF(J57="not found","not in hayday.info",IF(C57="","no Fandom value",IF(IFERROR(INDEX(hayday_info!$C$2:$C$349,MATCH($A57,hayday_info!$A$2:$A$349,0)),"not found")=C57,"match","differs"))) -> match
A58: Wooly Chaps | B58: Sewing Machine | C58: 21 | D58: 90 | E58: 76 | F58: 309 | G58: 37 | I58: Hay Day Wiki (Fandom) https://hayday.fandom.com/wiki/Sewing_Machine | J58: =IFERROR(INDEX(hayday_info!$D$2:$D$349,MATCH($A58,hayday_info!$A$2:$A$349,0)),"not found") -> 76 | K58: =IF(J58="not found","not in hayday.info",IF(J58=E58,"matches mastered",IF(J58=D58,"matches normal","differs"))) -> matches mastered | L58: =IFERROR(INDEX(hayday_info!$E$2:$E$349,MATCH($A58,hayday_info!$A$2:$A$349,0)),"not found") -> 309 | M58: =IF(L58="not found","not in hayday.info",IF(F58="","no Fandom value",IF(L58=F58,"match","differs"))) -> match | N58: =IFERROR(INDEX(hayday_info!$F$2:$F$349,MATCH($A58,hayday_info!$A$2:$A$349,0)),"not found") -> 37 | O58: =IF(N58="not found","not in hayday.info",IF(G58="","no Fandom value",IF(N58=G58,"match","differs"))) -> match | P58: =IF(J58="not found","not in hayday.info",IF(C58="","no Fandom value",IF(IFERROR(INDEX(hayday_info!$C$2:$C$349,MATCH($A58,hayday_info!$A$2:$A$349,0)),"not found")=C58,"match","differs"))) -> match
A59: Violet Dress | B59: Sewing Machine | C59: 25 | D59: 135 | E59: 114 | F59: 327 | G59: 39 | I59: Hay Day Wiki (Fandom) https://hayday.fandom.com/wiki/Sewing_Machine | J59: =IFERROR(INDEX(hayday_info!$D$2:$D$349,MATCH($A59,hayday_info!$A$2:$A$349,0)),"not found") -> 114 | K59: =IF(J59="not found","not in hayday.info",IF(J59=E59,"matches mastered",IF(J59=D59,"matches normal","differs"))) -> matches mastered | L59: =IFERROR(INDEX(hayday_info!$E$2:$E$349,MATCH($A59,hayday_info!$A$2:$A$349,0)),"not found") -> 327 | M59: =IF(L59="not found","not in hayday.info",IF(F59="","no Fandom value",IF(L59=F59,"match","differs"))) -> match | N59: =IFERROR(INDEX(hayday_info!$F$2:$F$349,MATCH($A59,hayday_info!$A$2:$A$349,0)),"not found") -> 39 | O59: =IF(N59="not found","not in hayday.info",IF(G59="","no Fandom value",IF(N59=G59,"match","differs"))) -> match | P59: =IF(J59="not found","not in hayday.info",IF(C59="","no Fandom value",IF(IFERROR(INDEX(hayday_info!$C$2:$C$349,MATCH($A59,hayday_info!$A$2:$A$349,0)),"not found")=C59,"match","differs"))) -> match
A60: Pillow | B60: Sewing Machine | C60: 51 | D60: 180 | E60: 153 | F60: 676 | G60: 81 | I60: Hay Day Wiki (Fandom) https://hayday.fandom.com/wiki/Sewing_Machine | J60: =IFERROR(INDEX(hayday_info!$D$2:$D$349,MATCH($A60,hayday_info!$A$2:$A$349,0)),"not found") -> 153 | K60: =IF(J60="not found","not in hayday.info",IF(J60=E60,"matches mastered",IF(J60=D60,"matches normal","differs"))) -> matches mastered | L60: =IFERROR(INDEX(hayday_info!$E$2:$E$349,MATCH($A60,hayday_info!$A$2:$A$349,0)),"not found") -> 676 | M60: =IF(L60="not found","not in hayday.info",IF(F60="","no Fandom value",IF(L60=F60,"match","differs"))) -> match | N60: =IFERROR(INDEX(hayday_info!$F$2:$F$349,MATCH($A60,hayday_info!$A$2:$A$349,0)),"not found") -> 81 | O60: =IF(N60="not found","not in hayday.info",IF(G60="","no Fandom value",IF(N60=G60,"match","differs"))) -> match | P60: =IF(J60="not found","not in hayday.info",IF(C60="","no Fandom value",IF(IFERROR(INDEX(hayday_info!$C$2:$C$349,MATCH($A60,hayday_info!$A$2:$A$349,0)),"not found")=C60,"match","differs"))) -> match
A61: Blanket | B61: Sewing Machine | C61: 59 | D61: 210 | E61: 178 | F61: 1098 | G61: 131 | I61: Hay Day Wiki (Fandom) https://hayday.fandom.com/wiki/Sewing_Machine | J61: =IFERROR(INDEX(hayday_info!$D$2:$D$349,MATCH($A61,hayday_info!$A$2:$A$349,0)),"not found") -> 178 | K61: =IF(J61="not found","not in hayday.info",IF(J61=E61,"matches mastered",IF(J61=D61,"matches normal","differs"))) -> matches mastered | L61: =IFERROR(INDEX(hayday_info!$E$2:$E$349,MATCH($A61,hayday_info!$A$2:$A$349,0)),"not found") -> 1098 | M61: =IF(L61="not found","not in hayday.info",IF(F61="","no Fandom value",IF(L61=F61,"match","differs"))) -> match | N61: =IFERROR(INDEX(hayday_info!$F$2:$F$349,MATCH($A61,hayday_info!$A$2:$A$349,0)),"not found") -> 131 | O61: =IF(N61="not found","not in hayday.info",IF(G61="","no Fandom value",IF(N61=G61,"match","differs"))) -> match | P61: =IF(J61="not found","not in hayday.info",IF(C61="","no Fandom value",IF(IFERROR(INDEX(hayday_info!$C$2:$C$349,MATCH($A61,hayday_info!$A$2:$A$349,0)),"not found")=C61,"match","differs"))) -> match
A62: Carrot juice | B62: Juice Press | C62: 26 | D62: 30 | E62: 25 | F62: 46 | G62: 6 | I62: Hay Day Wiki (Fandom) https://hayday.fandom.com/wiki/Juice_Press | J62: =IFERROR(INDEX(hayday_info!$D$2:$D$349,MATCH($A62,hayday_info!$A$2:$A$349,0)),"not found") -> 25 | K62: =IF(J62="not found","not in hayday.info",IF(J62=E62,"matches mastered",IF(J62=D62,"matches normal","differs"))) -> matches mastered | L62: =IFERROR(INDEX(hayday_info!$E$2:$E$349,MATCH($A62,hayday_info!$A$2:$A$349,0)),"not found") -> 46 | M62: =IF(L62="not found","not in hayday.info",IF(F62="","no Fandom value",IF(L62=F62,"match","differs"))) -> match | N62: =IFERROR(INDEX(hayday_info!$F$2:$F$349,MATCH($A62,hayday_info!$A$2:$A$349,0)),"not found") -> 6 | O62: =IF(N62="not found","not in hayday.info",IF(G62="","no Fandom value",IF(N62=G62,"match","differs"))) -> match | P62: =IF(J62="not found","not in hayday.info",IF(C62="","no Fandom value",IF(IFERROR(INDEX(hayday_info!$C$2:$C$349,MATCH($A62,hayday_info!$A$2:$A$349,0)),"not found")=C62,"match","differs"))) -> match
... A89: Grape jam | B89: Jam Maker | C89: 85 | D89: 390 | E89: 330 | F89: 162 | G89: 19 | I89: Hay Day Wiki (Fandom) https://hayday.fandom.com/wiki/Jam_Maker | J89: =IFERROR(INDEX(hayday_info!$D$2:$D$349,MATCH($A89,hayday_info!$A$2:$A$349,0)),"not found") -> 331 | K89: =IF(J89="not found","not in hayday.info",IF(J89=E89,"matches mastered",IF(J89=D89,"matches normal","differs"))) -> differs | L89: =IFERROR(INDEX(hayday_info!$E$2:$E$349,MATCH($A89,hayday_info!$A$2:$A$349,0)),"not found") -> 162 | M89: =IF(L89="not found","not in hayday.info",IF(F89="","no Fandom value",IF(L89=F89,"match","differs"))) -> match | N89: =IFERROR(INDEX(hayday_info!$F$2:$F$349,MATCH($A89,hayday_info!$A$2:$A$349,0)),"not found") -> 19 | O89: =IF(N89="not found","not in hayday.info",IF(G89="","no Fandom value",IF(N89=G89,"match","differs"))) -> match | P89: =IF(J89="not found","not in hayday.info",IF(C89="","no Fandom value",IF(IFERROR(INDEX(hayday_info!$C$2:$C$349,MATCH($A89,hayday_info!$A$2:$A$349,0)),"not found")=C89,"match","differs"))) -> match
A90: Plum jam | B90: Jam Maker | C90: 94 | D90: 300 | E90: 255 | H90: Sell price and XP not listed on the page | I90: Hay Day Wiki (Fandom) https://hayday.fandom.com/wiki/Jam_Maker | J90: =IFERROR(INDEX(hayday_info!$D$2:$D$349,MATCH($A90,hayday_info!$A$2:$A$349,0)),"not found") -> 255 | K90: =IF(J90="not found","not in hayday.info",IF(J90=E90,"matches mastered",IF(J90=D90,"matches normal","differs"))) -> matches mastered | L90: =IFERROR(INDEX(hayday_info!$E$2:$E$349,MATCH($A90,hayday_info!$A$2:$A$349,0)),"not found") -> 385 | M90: =IF(L90="not found","not in hayday.info",IF(F90="","no Fandom value",IF(L90=F90,"match","differs"))) -> no Fandom value | N90: =IFERROR(INDEX(hayday_info!$F$2:$F$349,MATCH($A90,hayday_info!$A$2:$A$349,0)),"not found") -> 46 | O90: =IF(N90="not found","not in hayday.info",IF(G90="","no Fandom value",IF(N90=G90,"match","differs"))) -> no Fandom value | P90: =IF(J90="not found","not in hayday.info",IF(C90="","no Fandom value",IF(IFERROR(INDEX(hayday_info!$C$2:$C$349,MATCH($A90,hayday_info!$A$2:$A$349,0)),"not found")=C90,"match","differs"))) -> match
A91: Bracelet | B91: Jeweler | C91: 38 | D91: 120 | E91: 102 | F91: 514 | G91: 61 | I91: Hay Day Wiki (Fandom) https://hayday.fandom.com/wiki/Jeweler | J91: =IFERROR(INDEX(hayday_info!$D$2:$D$349,MATCH($A91,hayday_info!$A$2:$A$349,0)),"not found") -> 102 | K91: =IF(J91="not found","not in hayday.info",IF(J91=E91,"matches mastered",IF(J91=D91,"matches normal","differs"))) -> matches mastered | L91: =IFERROR(INDEX(hayday_info!$E$2:$E$349,MATCH($A91,hayday_info!$A$2:$A$349,0)),"not found") -> 514 | M91: =IF(L91="not found","not in hayday.info",IF(F91="","no Fandom value",IF(L91=F91,"match","differs"))) -> match | N91: =IFERROR(INDEX(hayday_info!$F$2:$F$349,MATCH($A91,hayday_info!$A$2:$A$349,0)),"not found") -> 61 | O91: =IF(N91="not found","not in hayday.info",IF(G91="","no Fandom value",IF(N91=G91,"match","differs"))) -> match | P91: =IF(J91="not found","not in hayday.info",IF(C91="","no Fandom value",IF(IFERROR(INDEX(hayday_info!$C$2:$C$349,MATCH($A91,hayday_info!$A$2:$A$349,0)),"not found")=C91,"match","differs"))) -> match
A92: Necklace | B92: Jeweler | C92: 39 | D92: 180 | E92: 153 | F92: 727 | G92: 87 | I92: Hay Day Wiki (Fandom) https://hayday.fandom.com/wiki/Jeweler | J92: =IFERROR(INDEX(hayday_info!$D$2:$D$349,MATCH($A92,hayday_info!$A$2:$A$349,0)),"not found") -> 153 | K92: =IF(J92="not found","not in hayday.info",IF(J92=E92,"matches mastered",IF(J92=D92,"matches normal","differs"))) -> matches mastered | L92: =IFERROR(INDEX(hayday_info!$E$2:$E$349,MATCH($A92,hayday_info!$A$2:$A$349,0)),"not found") -> 727 | M92: =IF(L92="not found","not in hayday.info",IF(F92="","no Fandom value",IF(L92=F92,"match","differs"))) -> match | N92: =IFERROR(INDEX(hayday_info!$F$2:$F$349,MATCH($A92,hayday_info!$A$2:$A$349,0)),"not found") -> 87 | O92: =IF(N92="not found","not in hayday.info",IF(G92="","no Fandom value",IF(N92=G92,"match","differs"))) -> match | P92: =IF(J92="not found","not in hayday.info",IF(C92="","no Fandom value",IF(IFERROR(INDEX(hayday_info!$C$2:$C$349,MATCH($A92,hayday_info!$A$2:$A$349,0)),"not found")=C92,"match","differs"))) -> match
A93: Diamond Ring | B93: Jeweler | C93: 40 | D93: 240 | E93: 204 | F93: 824 | G93: 98 | I93: Hay Day Wiki (Fandom) https://hayday.fandom.com/wiki/Jeweler | J93: =IFERROR(INDEX(hayday_info!$D$2:$D$349,MATCH($A93,hayday_info!$A$2:$A$349,0)),"not found") -> 204 | K93: =IF(J93="not found","not in hayday.info",IF(J93=E93,"matches mastered",IF(J93=D93,"matches normal","differs"))) -> matches mastered | L93: =IFERROR(INDEX(hayday_info!$E$2:$E$349,MATCH($A93,hayday_info!$A$2:$A$349,0)),"not found") -> 824 | M93: =IF(L93="not found","not in hayday.info",IF(F93="","no Fandom value",IF(L93=F93,"match","differs"))) -> match | N93: =IFERROR(INDEX(hayday_info!$F$2:$F$349,MATCH($A93,hayday_info!$A$2:$A$349,0)),"not found") -> 98 | O93: =IF(N93="not found","not in hayday.info",IF(G93="","no Fandom value",IF(N93=G93,"match","differs"))) -> match | P93: =IF(J93="not found","not in hayday.info",IF(C93="","no Fandom value",IF(IFERROR(INDEX(hayday_info!$C$2:$C$349,MATCH($A93,hayday_info!$A$2:$A$349,0)),"not found")=C93,"match","differs"))) -> match
