Workbook

Sheet merged_v2
A1: Product | B1: Machine | C1: Kind (Fandom) | D1: Level | E1: Level (hayday.info) | F1: Level (Fandom) | G1: Time hayday.info (min) | H1: Time normal (Fandom, min) | I1: Time mastered (Fandom, min) | J1: hayday.info time basis | K1: Sell price | L1: Sell price (hayday.info) | M1: Sell price (Fandom) | N1: XP | O1: XP (hayday.info) | P1: XP (Fandom) | Q1: Profit/hr (site) | R1: XP/hr (site) | S1: Flag | T1: Found in | U1: Status | V1: Conflict fields | W1: Fandom internal conflict | X1: Ingredients (Fandom) | Y1: Icon file (Fandom) | Z1: Icon (local) | AA1: Source | AB1: Fandom page | AC1: hayday.info name
A2: Egg | B2: Animal Products | C2: Animal good | D2: =IF(E2<>"",E2,IF(F2<>"",F2,"")) | E2: 1 | F2: 1 | G2: 20 | H2: 20 | J2: =IF(OR(G2="",AND(H2="",I2="")),"n/a",IF(G2=I2,"mastered",IF(G2=H2,"normal","differs"))) | K2: =IF(L2<>"",L2,IF(M2<>"",M2,"")) | L2: 18 | M2: 18 | N2: =IF(O2<>"",O2,IF(P2<>"",P2,"")) | O2: 2 | P2: 2 | Q2: 33 | R2: 6 | S2: =IF(Q2="","",IF(Q2<0,"negative profit",IF(Q2>Notes!$B$4,"unusually high - verify",""))) | T2: both | U2: =IF(T2<>"both",T2&" only",IF(V2="","agree","conflict")) | V2: =IF(T2="both",TRIM(IF(AND(E2<>"",F2<>"",E2<>F2),"level ","")&IF(AND(L2<>"",M2<>"",L2<>M2),"price ","")&IF(AND(O2<>"",P2<>"",O2<>P2),"xp ","")&IF(J2="differs","time","")),"") | Y2: Egg.png | Z2: icons/Animal Products/Egg.png | AA2: hayday.info /api/production-data (2026-10-13) + Hay Day Wiki infobox via MediaWiki API (2026-10-13) | AB2: https://hayday.fandom.com/wiki/Egg | AC2: Egg
A3: Milk | B3: Animal Products | C3: Animal good | D3: =IF(E3<>"",E3,IF(F3<>"",F3,"")) | E3: 6 | F3: 6 | G3: 60 | H3: 60 | J3: =IF(OR(G3="",AND(H3="",I3="")),"n/a",IF(G3=I3,"mastered",IF(G3=H3,"normal","differs"))) | K3: =IF(L3<>"",L3,IF(M3<>"",M3,"")) | L3: 32 | M3: 32 | N3: =IF(O3<>"",O3,IF(P3<>"",P3,"")) | O3: 3 | P3: 3 | Q3: 18 | R3: 3 | S3: =IF(Q3="","",IF(Q3<0,"negative profit",IF(Q3>Notes!$B$4,"unusually high - verify",""))) | T3: both | U3: =IF(T3<>"both",T3&" only",IF(V3="","agree","conflict")) | V3: =IF(T3="both",TRIM(IF(AND(E3<>"",F3<>"",E3<>F3),"level ","")&IF(AND(L3<>"",M3<>"",L3<>M3),"price ","")&IF(AND(O3<>"",P3<>"",O3<>P3),"xp ","")&IF(J3="differs","time","")),"") | Y3: Milk.png | Z3: icons/Animal Products/Milk.png | AA3: hayday.info /api/production-data (2026-10-13) + Hay Day Wiki infobox via MediaWiki API (2026-10-13) | AB3: https://hayday.fandom.com/wiki/Milk | AC3: Milk
A4: Bacon | B4: Animal Products | C4: Animal good | D4: =IF(E4<>"",E4,IF(F4<>"",F4,"")) | E4: 10 | F4: 10 | G4: 240 | H4: 240 | J4: =IF(OR(G4="",AND(H4="",I4="")),"n/a",IF(G4=I4,"mastered",IF(G4=H4,"normal","differs"))) | K4: =IF(L4<>"",L4,IF(M4<>"",M4,"")) | L4: 50 | M4: 50 | N4: =IF(O4<>"",O4,IF(P4<>"",P4,"")) | O4: 5 | P4: 5 | Q4: -2.5 | R4: 1.25 | S4: =IF(Q4="","",IF(Q4<0,"negative profit",IF(Q4>Notes!$B$4,"unusually high - verify",""))) | T4: both | U4: =IF(T4<>"both",T4&" only",IF(V4="","agree","conflict")) | V4: =IF(T4="both",TRIM(IF(AND(E4<>"",F4<>"",E4<>F4),"level ","")&IF(AND(L4<>"",M4<>"",L4<>M4),"price ","")&IF(AND(O4<>"",P4<>"",O4<>P4),"xp ","")&IF(J4="differs","time","")),"") | Y4: Bacon.png | Z4: icons/Animal Products/Bacon.png | AA4: hayday.info /api/production-data (2026-10-13) + Hay Day Wiki infobox via MediaWiki API (2026-10-13) | AB4: https://hayday.fandom.com/wiki/Bacon | AC4: Bacon
A5: Wool | B5: Animal Products | C5: Animal good | D5: =IF(E5<>"",E5,IF(F5<>"",F5,"")) | E5: 16 | F5: 16 | G5: 360 | H5: 360 | J5: =IF(OR(G5="",AND(H5="",I5="")),"n/a",IF(G5=I5,"mastered",IF(G5=H5,"normal","differs"))) | K5: =IF(L5<>"",L5,IF(M5<>"",M5,"")) | L5: 54 | M5: 54 | N5: =IF(O5<>"",O5,IF(P5<>"",P5,"")) | O5: 5 | P5: 5 | Q5: -0.83 | R5: 0.83 | S5: =IF(Q5="","",IF(Q5<0,"negative profit",IF(Q5>Notes!$B$4,"unusually high - verify",""))) | T5: both | U5: =IF(T5<>"both",T5&" only",IF(V5="","agree","conflict")) | V5: =IF(T5="both",TRIM(IF(AND(E5<>"",F5<>"",E5<>F5),"level ","")&IF(AND(L5<>"",M5<>"",L5<>M5),"price ","")&IF(AND(O5<>"",P5<>"",O5<>P5),"xp ","")&IF(J5="differs","time","")),"") | Y5: Wool.png | Z5: icons/Animal Products/Wool.png | AA5: hayday.info /api/production-data (2026-10-13) + Hay Day Wiki infobox via MediaWiki API (2026-10-13) | AB5: https://hayday.fandom.com/wiki/Wool | AC5: Wool
A6: Goat Milk | B6: Animal Products | C6: Animal good | D6: =IF(E6<>"",E6,IF(F6<>"",F6,"")) | E6: 32 | F6: 32 | G6: 480 | H6: 480 | J6: =IF(OR(G6="",AND(H6="",I6="")),"n/a",IF(G6=I6,"mastered",IF(G6=H6,"normal","differs"))) | K6: =IF(L6<>"",L6,IF(M6<>"",M6,"")) | L6: 64 | M6: 64 | N6: =IF(O6<>"",O6,IF(P6<>"",P6,"")) | O6: 6 | P6: 6 | Q6: -1.25 | R6: 0.75 | S6: =IF(Q6="","",IF(Q6<0,"negative profit",IF(Q6>Notes!$B$4,"unusually high - verify",""))) | T6: both | U6: =IF(T6<>"both",T6&" only",IF(V6="","agree","conflict")) | V6: =IF(T6="both",TRIM(IF(AND(E6<>"",F6<>"",E6<>F6),"level ","")&IF(AND(L6<>"",M6<>"",L6<>M6),"price ","")&IF(AND(O6<>"",P6<>"",O6<>P6),"xp ","")&IF(J6="differs","time","")),"") | Y6: Goat Milk.png | Z6: icons/Animal Products/Goat Milk.png | AA6: hayday.info /api/production-data (2026-10-13) + Hay Day Wiki infobox via MediaWiki API (2026-10-13) | AB6: https://hayday.fandom.com/wiki/Goat_Milk | AC6: Goat milk
A7: Lamb Chop | B7: Animal Products | C7: Animal good | D7: =IF(E7<>"",E7,IF(F7<>"",F7,"")) | F7: 25 | H7: 30 | J7: =IF(OR(G7="",AND(H7="",I7="")),"n/a",IF(G7=I7,"mastered",IF(G7=H7,"normal","differs"))) | K7: =IF(L7<>"",L7,IF(M7<>"",M7,"")) | M7: 36 | N7: =IF(O7<>"",O7,IF(P7<>"",P7,"")) | P7: 4 | S7: =IF(Q7="","",IF(Q7<0,"negative profit",IF(Q7>Notes!$B$4,"unusually high - verify",""))) | T7: Fandom | U7: =IF(T7<>"both",T7&" only",IF(V7="","agree","conflict")) | V7: =IF(T7="both",TRIM(IF(AND(E7<>"",F7<>"",E7<>F7),"level ","")&IF(AND(L7<>"",M7<>"",L7<>M7),"price ","")&IF(AND(O7<>"",P7<>"",O7<>P7),"xp ","")&IF(J7="differs","time","")),"") | Y7: Lamb Chop.png | Z7: icons/Animal Products/Lamb Chop.png | AA7: Hay Day Wiki infobox via MediaWiki API (2026-10-13) | AB7: https://hayday.fandom.com/wiki/Lamb_Chop
A8: Fish Fillet | B8: Animal Products | C8: Animal good | D8: =IF(E8<>"",E8,IF(F8<>"",F8,"")) | F8: 27 | J8: =IF(OR(G8="",AND(H8="",I8="")),"n/a",IF(G8=I8,"mastered",IF(G8=H8,"normal","differs"))) | K8: =IF(L8<>"",L8,IF(M8<>"",M8,"")) | M8: 54 | N8: =IF(O8<>"",O8,IF(P8<>"",P8,"")) | P8: 4 | S8: =IF(Q8="","",IF(Q8<0,"negative profit",IF(Q8>Notes!$B$4,"unusually high - verify",""))) | T8: Fandom | U8: =IF(T8<>"both",T8&" only",IF(V8="","agree","conflict")) | V8: =IF(T8="both",TRIM(IF(AND(E8<>"",F8<>"",E8<>F8),"level ","")&IF(AND(L8<>"",M8<>"",L8<>M8),"price ","")&IF(AND(O8<>"",P8<>"",O8<>P8),"xp ","")&IF(J8="differs","time","")),"") | Y8: Fish Fillet.png | Z8: icons/Animal Products/Fish Fillet.png | AA8: Hay Day Wiki infobox via MediaWiki API (2026-10-13) | AB8: https://hayday.fandom.com/wiki/Fish_Fillet
A9: Mussel Meat | B9: Animal Products | C9: Animal good | D9: =IF(E9<>"",E9,IF(F9<>"",F9,"")) | F9: 27 | H9: 360 | J9: =IF(OR(G9="",AND(H9="",I9="")),"n/a",IF(G9=I9,"mastered",IF(G9=H9,"normal","differs"))) | K9: =IF(L9<>"",L9,IF(M9<>"",M9,"")) | M9: 28 | N9: =IF(O9<>"",O9,IF(P9<>"",P9,"")) | P9: 8 | S9: =IF(Q9="","",IF(Q9<0,"negative profit",IF(Q9>Notes!$B$4,"unusually high - verify",""))) | T9: Fandom | U9: =IF(T9<>"both",T9&" only",IF(V9="","agree","conflict")) | V9: =IF(T9="both",TRIM(IF(AND(E9<>"",F9<>"",E9<>F9),"level ","")&IF(AND(L9<>"",M9<>"",L9<>M9),"price ","")&IF(AND(O9<>"",P9<>"",O9<>P9),"xp ","")&IF(J9="differs","time","")),"") | Y9: Mussel Meat.png | Z9: icons/Animal Products/Mussel Meat.png | AA9: Hay Day Wiki infobox via MediaWiki API (2026-10-13) | AB9: https://hayday.fandom.com/wiki/Mussel_Meat
A10: Peanuts | B10: Animal Products | C10: Animal good | D10: =IF(E10<>"",E10,IF(F10<>"",F10,"")) | F10: 62 | H10: 300 | J10: =IF(OR(G10="",AND(H10="",I10="")),"n/a",IF(G10=I10,"mastered",IF(G10=H10,"normal","differs"))) | K10: =IF(L10<>"",L10,IF(M10<>"",M10,"")) | M10: 234 | N10: =IF(O10<>"",O10,IF(P10<>"",P10,"")) | P10: 43 | S10: =IF(Q10="","",IF(Q10<0,"negative profit",IF(Q10>Notes!$B$4,"unusually high - verify",""))) | T10: Fandom | U10: =IF(T10<>"both",T10&" only",IF(V10="","agree","conflict")) | V10: =IF(T10="both",TRIM(IF(AND(E10<>"",F10<>"",E10<>F10),"level ","")&IF(AND(L10<>"",M10<>"",L10<>M10),"price ","")&IF(AND(O10<>"",P10<>"",O10<>P10),"xp ","")&IF(J10="differs","time","")),"") | Y10: Peanuts.png | Z10: icons/Animal Products/Peanuts.png | AA10: Hay Day Wiki infobox via MediaWiki API (2026-10-13) | AB10: https://hayday.fandom.com/wiki/Peanuts
A11: Pancake | B11: BBQ Grill | C11: Product | D11: =IF(E11<>"",E11,IF(F11<>"",F11,"")) | E11: 9 | F11: 9 | G11: 25 | H11: 30 | I11: 25 | J11: =IF(OR(G11="",AND(H11="",I11="")),"n/a",IF(G11=I11,"mastered",IF(G11=H11,"normal","differs"))) | K11: =IF(L11<>"",L11,IF(M11<>"",M11,"")) | L11: 108 | M11: 108 | N11: =IF(O11<>"",O11,IF(P11<>"",P11,"")) | O11: 13 | P11: 13 | Q11: 51.76 | R11: 30.59 | S11: =IF(Q11="","",IF(Q11<0,"negative profit",IF(Q11>Notes!$B$4,"unusually high - verify",""))) | T11: both | U11: =IF(T11<>"both",T11&" only",IF(V11="","agree","conflict")) | V11: =IF(T11="both",TRIM(IF(AND(E11<>"",F11<>"",E11<>F11),"level ","")&IF(AND(L11<>"",M11<>"",L11<>M11),"price ","")&IF(AND(O11<>"",P11<>"",O11<>P11),"xp ","")&IF(J11="differs","time","")),"") | X11: Egg x3; Brown Sugar x1 | Y11: Pancake.png | Z11: icons/BBQ Grill/Pancake.png | AA11: hayday.info /api/production-data (2026-10-13) + Hay Day Wiki infobox via MediaWiki API (2026-10-13) | AB11: https://hayday.fandom.com/wiki/Pancake | AC11: Pancake
A12: Bacon and Eggs | B12: BBQ Grill | C12: Product | D12: =IF(E12<>"",E12,IF(F12<>"",F12,"")) | E12: 11 | F12: 11 | G12: 51 | H12: 60 | I12: 51 | J12: =IF(OR(G12="",AND(H12="",I12="")),"n/a",IF(G12=I12,"mastered",IF(G12=H12,"normal","differs"))) | K12: =IF(L12<>"",L12,IF(M12<>"",M12,"")) | L12: 201 | M12: 201 | N12: =IF(O12<>"",O12,IF(P12<>"",P12,"")) | O12: 24 | P12: 24 | Q12: 34.12 | R12: 28.24 | S12: =IF(Q12="","",IF(Q12<0,"negative profit",IF(Q12>Notes!$B$4,"unusually high - verify",""))) | T12: both | U12: =IF(T12<>"both",T12&" only",IF(V12="","agree","conflict")) | V12: =IF(T12="both",TRIM(IF(AND(E12<>"",F12<>"",E12<>F12),"level ","")&IF(AND(L12<>"",M12<>"",L12<>M12),"price ","")&IF(AND(O12<>"",P12<>"",O12<>P12),"xp ","")&IF(J12="differs","time","")),"") | X12: Egg x4; Bacon x2 | Y12: Bacon_and_Eggs.png | Z12: icons/BBQ Grill/Bacon and Eggs.png | AA12: hayday.info /api/production-data (2026-10-13) + Hay Day Wiki infobox via MediaWiki API (2026-10-13) | AB12: https://hayday.fandom.com/wiki/Bacon_and_Eggs | AC12: Bacon and eggs
A13: Hamburger | B13: BBQ Grill | C13: Product | D13: =IF(E13<>"",E13,IF(F13<>"",F13,"")) | E13: 18 | F13: 18 | G13: 102 | H13: 120 | I13: 102 | J13: =IF(OR(G13="",AND(H13="",I13="")),"n/a",IF(G13=I13,"mastered",IF(G13=H13,"normal","differs"))) | K13: =IF(L13<>"",L13,IF(M13<>"",M13,"")) | L13: 180 | M13: 180 | N13: =IF(O13<>"",O13,IF(P13<>"",P13,"")) | O13: 22 | P13: 22 | Q13: 22.35 | R13: 12.94 | S13: =IF(Q13="","",IF(Q13<0,"negative profit",IF(Q13>Notes!$B$4,"unusually high - verify",""))) | T13: both | U13: =IF(T13<>"both",T13&" only",IF(V13="","agree","conflict")) | V13: =IF(T13="both",TRIM(IF(AND(E13<>"",F13<>"",E13<>F13),"level ","")&IF(AND(L13<>"",M13<>"",L13<>M13),"price ","")&IF(AND(O13<>"",P13<>"",O13<>P13),"xp ","")&IF(J13="differs","time","")),"") | X13: Bread x2; Bacon x2 | Y13: Hamburger.png | Z13: icons/BBQ Grill/Hamburger.png | AA13: hayday.info /api/production-data (2026-10-13) + Hay Day Wiki infobox via MediaWiki API (2026-10-13) | AB13: https://hayday.fandom.com/wiki/Hamburger | AC13: Hamburger
A14: Fish Burger | B14: BBQ Grill | C14: Product | D14: =IF(E14<>"",E14,IF(F14<>"",F14,"")) | E14: 27 | F14: 27 | G14: 102 | H14: 120 | I14: 102 | J14: =IF(OR(G14="",AND(H14="",I14="")),"n/a",IF(G14=I14,"mastered",IF(G14=H14,"normal","differs"))) | K14: =IF(L14<>"",L14,IF(M14<>"",M14,"")) | L14: 226 | M14: 226 | N14: =IF(O14<>"",O14,IF(P14<>"",P14,"")) | O14: 27 | P14: 27 | Q14: 23.53 | R14: 15.88 | S14: =IF(Q14="","",IF(Q14<0,"negative profit",IF(Q14>Notes!$B$4,"unusually high - verify",""))) | T14: both | U14: =IF(T14<>"both",T14&" only",IF(V14="","agree","conflict")) | V14: =IF(T14="both",TRIM(IF(AND(E14<>"",F14<>"",E14<>F14),"level ","")&IF(AND(L14<>"",M14<>"",L14<>M14),"price ","")&IF(AND(O14<>"",P14<>"",O14<>P14),"xp ","")&IF(J14="differs","time","")),"") | X14: Fish Fillet x2; Chili Pepper x1; Bread x2 | Y14: Fish Burger.png | Z14: icons/BBQ Grill/Fish Burger.png | AA14: hayday.info /api/production-data (2026-10-13) + Hay Day Wiki infobox via MediaWiki API (2026-10-13) | AB14: https://hayday.fandom.com/wiki/Fish_Burger | AC14: Fish burger
A15: Roasted Tomatoes | B15: BBQ Grill | C15: Product | D15: =IF(E15<>"",E15,IF(F15<>"",F15,"")) | E15: 30 | F15: 30 | G15: 76 | H15: 90 | I15: 76 | J15: =IF(OR(G15="",AND(H15="",I15="")),"n/a",IF(G15=I15,"mastered",IF(G15=H15,"normal","differs"))) | K15: =IF(L15<>"",L15,IF(M15<>"",M15,"")) | L15: 118 | M15: 118 | N15: =IF(O15<>"",O15,IF(P15<>"",P15,"")) | O15: 14 | P15: 14 | Q15: 25.1 | R15: 10.98 | S15: =IF(Q15="","",IF(Q15<0,"negative profit",IF(Q15>Notes!$B$4,"unusually high - verify",""))) | T15: both | U15: =IF(T15<>"both",T15&" only",IF(V15="","agree","conflict")) | V15: =IF(T15="both",TRIM(IF(AND(E15<>"",F15<>"",E15<>F15),"level ","")&IF(AND(L15<>"",M15<>"",L15<>M15),"price ","")&IF(AND(O15<>"",P15<>"",O15<>P15),"xp ","")&IF(J15="differs","time","")),"") | X15: Tomato x2 | Y15: Roasted Tomatoes.png | Z15: icons/BBQ Grill/Roasted Tomatoes.png | AA15: hayday.info /api/production-data (2026-10-13) + Hay Day Wiki infobox via MediaWiki API (2026-10-13) | AB15: https://hayday.fandom.com/wiki/Roasted_Tomatoes | AC15: Roasted tomatoes
A16: Baked Potato | B16: BBQ Grill | C16: Product | D16: =IF(E16<>"",E16,IF(F16<>"",F16,"")) | E16: 35 | F16: 35 | G16: 29 | H16: 35 | I16: 29 | J16: =IF(OR(G16="",AND(H16="",I16="")),"n/a",IF(G16=I16,"mastered",IF(G16=H16,"normal","differs"))) | K16: =IF(L16<>"",L16,IF(M16<>"",M16,"")) | L16: 298 | M16: 298 | N16: =IF(O16<>"",O16,IF(P16<>"",P16,"")) | O16: 36 | P16: 36 | Q16: 36.3 | R16: 72.61 | S16: =IF(Q16="","",IF(Q16<0,"negative profit",IF(Q16>Notes!$B$4,"unusually high - verify",""))) | T16: both | U16: =IF(T16<>"both",T16&" only",IF(V16="","agree","conflict")) | V16: =IF(T16="both",TRIM(IF(AND(E16<>"",F16<>"",E16<>F16),"level ","")&IF(AND(L16<>"",M16<>"",L16<>M16),"price ","")&IF(AND(O16<>"",P16<>"",O16<>P16),"xp ","")&IF(J16="differs","time","")),"") | X16: Potato x2; Chili Pepper x1; Cream x1; Cheese x1 | Y16: Baked Potato.png | Z16: icons/BBQ Grill/Baked Potato.png | AA16: hayday.info /api/production-data (2026-10-13) + Hay Day Wiki infobox via MediaWiki API (2026-10-13) | AB16: https://hayday.fandom.com/wiki/Baked_Potato | AC16: Baked potato
A17: Fish and Chips | B17: BBQ Grill | C17: Product | D17: =IF(E17<>"",E17,IF(F17<>"",F17,"")) | E17: 41 | F17: 41 | G17: 76 | H17: 90 | I17: 76 | J17: =IF(OR(G17="",AND(H17="",I17="")),"n/a",IF(G17=I17,"mastered",IF(G17=H17,"normal","differs"))) | K17: =IF(L17<>"",L17,IF(M17<>"",M17,"")) | L17: 244 | M17: 244 | N17: =IF(O17<>"",O17,IF(P17<>"",P17,"")) | O17: 29 | P17: 29 | Q17: 21.96 | R17: 22.75 | S17: =IF(Q17="","",IF(Q17<0,"negative profit",IF(Q17>Notes!$B$4,"unusually high - verify",""))) | T17: both | U17: =IF(T17<>"both",T17&" only",IF(V17="","agree","conflict")) | V17: =IF(T17="both",TRIM(IF(AND(E17<>"",F17<>"",E17<>F17),"level ","")&IF(AND(L17<>"",M17<>"",L17<>M17),"price ","")&IF(AND(O17<>"",P17<>"",O17<>P17),"xp ","")&IF(J17="differs","time","")),"") | X17: Fish Fillet x2; Potato x3 | Y17: Fish and Chips.png | Z17: icons/BBQ Grill/Fish and Chips.png | AA17: hayday.info /api/production-data (2026-10-13) + Hay Day Wiki infobox via MediaWiki API (2026-10-13) | AB17: https://hayday.fandom.com/wiki/Fish_and_Chips | AC17: Fish and chips
A18: Lobster Skewer | B18: BBQ Grill | C18: Product | D18: =IF(E18<>"",E18,IF(F18<>"",F18,"")) | E18: 48 | F18: 48 | G18: 34 | H18: 40 | I18: 34 | J18: =IF(OR(G18="",AND(H18="",I18="")),"n/a",IF(G18=I18,"mastered",IF(G18=H18,"normal","differs"))) | K18: =IF(L18<>"",L18,IF(M18<>"",M18,"")) | L18: 417 | M18: 417 | N18: =IF(O18<>"",O18,IF(P18<>"",P18,"")) | O18: 50 | P18: 50 | Q18: 45.88 | R18: 88.24 | S18: =IF(Q18="","",IF(Q18<0,"negative profit",IF(Q18>Notes!$B$4,"unusually high - verify",""))) | T18: both | U18: =IF(T18<>"both",T18&" only",IF(V18="","agree","conflict")) | V18: =IF(T18="both",TRIM(IF(AND(E18<>"",F18<>"",E18<>F18),"level ","")&IF(AND(L18<>"",M18<>"",L18<>M18),"price ","")&IF(AND(O18<>"",P18<>"",O18<>P18),"xp ","")&IF(J18="differs","time","")),"") | X18: Lobster Tail x1; Chili Pepper x1; Honey x1 | Y18: Lobster Skewer.png | Z18: icons/BBQ Grill/Lobster Skewer.png | AA18: hayday.info /api/production-data (2026-10-13) + Hay Day Wiki infobox via MediaWiki API (2026-10-13) | AB18: https://hayday.fandom.com/wiki/Lobster_Skewer | AC18: Lobster skewer
A19: Garlic Bread | B19: BBQ Grill | C19: product | D19: =IF(E19<>"",E19,IF(F19<>"",F19,"")) | E19: 60 | F19: 60 | G19: 12 | H19: 15 | I19: 12 | J19: =IF(OR(G19="",AND(H19="",I19="")),"n/a",IF(G19=I19,"mastered",IF(G19=H19,"normal","differs"))) | K19: =IF(L19<>"",L19,IF(M19<>"",M19,"")) | L19: 198 | M19: 198 | N19: =IF(O19<>"",O19,IF(P19<>"",P19,"")) | O19: 24 | P19: 24 | Q19: 84.71 | R19: 112.94 | S19: =IF(Q19="","",IF(Q19<0,"negative profit",IF(Q19>Notes!$B$4,"unusually high - verify",""))) | T19: both | U19: =IF(T19<>"both",T19&" only",IF(V19="","agree","conflict")) | V19: =IF(T19="both",TRIM(IF(AND(E19<>"",F19<>"",E19<>F19),"level ","")&IF(AND(L19<>"",M19<>"",L19<>M19),"price ","")&IF(AND(O19<>"",P19<>"",O19<>P19),"xp ","")&IF(J19="differs","time","")),"") | X19: Bread x2; Butter x1; Garlic x4 | Y19: Garlic Bread.png | Z19: icons/BBQ Grill/Garlic Bread.png | AA19: hayday.info /api/production-data (2026-10-13) + Hay Day Wiki infobox via MediaWiki API (2026-10-13) | AB19: https://hayday.fandom.com/wiki/Garlic_Bread | AC19: Garlic bread
A20: Grilled Onion | B20: BBQ Grill | C20: Product | D20: =IF(E20<>"",E20,IF(F20<>"",F20,"")) | E20: 68 | F20: 68 | G20: 51 | H20: 60 | I20: 51 | J20: =IF(OR(G20="",AND(H20="",I20="")),"n/a",IF(G20=I20,"mastered",IF(G20=H20,"normal","differs"))) | K20: =IF(L20<>"",L20,IF(M20<>"",M20,"")) | L20: 190 | M20: 190 | N20: =IF(O20<>"",O20,IF(P20<>"",P20,"")) | O20: 23 | P20: 23 | Q20: 35.29 | R20: 27.06 | S20: =IF(Q20="","",IF(Q20<0,"negative profit",IF(Q20>Notes!$B$4,"unusually high - verify",""))) | T20: both | U20: =IF(T20<>"both",T20&" only",IF(V20="","agree","conflict")) | V20: =IF(T20="both",TRIM(IF(AND(E20<>"",F20<>"",E20<>F20),"level ","")&IF(AND(L20<>"",M20<>"",L20<>M20),"price ","")&IF(AND(O20<>"",P20<>"",O20<>P20),"xp ","")&IF(J20="differs","time","")),"") | X20: Butter x1; Onion x2 | Y20: Grilled Onion.png | Z20: icons/BBQ Grill/Grilled Onion.png | AA20: hayday.info /api/production-data (2026-10-13) + Hay Day Wiki infobox via MediaWiki API (2026-10-13) | AB20: https://hayday.fandom.com/wiki/Grilled_Onion | AC20: Grilled onion
A21: Winter Veggies | B21: BBQ Grill | C21: product | D21: =IF(E21<>"",E21,IF(F21<>"",F21,"")) | E21: 72 | F21: 72 | G21: 21 | H21: 25 | I21: 21 | J21: =IF(OR(G21="",AND(H21="",I21="")),"n/a",IF(G21=I21,"mastered",IF(G21=H21,"normal","differs"))) | K21: =IF(L21<>"",L21,IF(M21<>"",M21,"")) | L21: 198 | M21: 198 | N21: =IF(O21<>"",O21,IF(P21<>"",P21,"")) | O21: 24 | P21: 24 | Q21: 36.71 | R21: 67.76 | S21: =IF(Q21="","",IF(Q21<0,"negative profit",IF(Q21>Notes!$B$4,"unusually high - verify",""))) | T21: both | U21: =IF(T21<>"both",T21&" only",IF(V21="","agree","conflict")) | V21: =IF(T21="both",TRIM(IF(AND(E21<>"",F21<>"",E21<>F21),"level ","")&IF(AND(L21<>"",M21<>"",L21<>M21),"price ","")&IF(AND(O21<>"",P21<>"",O21<>P21),"xp ","")&IF(J21="differs","time","")),"") | X21: Beetroot x2; Carrot x2; Potato x2; Pumpkin x2 | Y21: Winter Veggies.png | Z21: icons/BBQ Grill/Winter Veggies.png | AA21: hayday.info /api/production-data (2026-10-13) + Hay Day Wiki infobox via MediaWiki API (2026-10-13) | AB21: https://hayday.fandom.com/wiki/Winter_Veggies | AC21: Winter veggies
A22: Stuffed Peppers | B22: BBQ Grill | C22: product | D22: =IF(E22<>"",E22,IF(F22<>"",F22,"")) | E22: 80 | F22: 80 | G22: 17 | H22: 20 | I22: 17 | J22: =IF(OR(G22="",AND(H22="",I22="")),"n/a",IF(G22=I22,"mastered",IF(G22=H22,"normal","differs"))) | K22: =IF(L22<>"",L22,IF(M22<>"",M22,"")) | L22: 352 | M22: 352 | N22: =IF(O22<>"",O22,IF(P22<>"",P22,"")) | O22: 42 | P22: 42 | Q22: 63.53 | R22: 148.24 | S22: =IF(Q22="","",IF(Q22<0,"negative profit",IF(Q22>Notes!$B$4,"unusually high - verify",""))) | T22: both | U22: =IF(T22<>"both",T22&" only",IF(V22="","agree","conflict")) | V22: =IF(T22="both",TRIM(IF(AND(E22<>"",F22<>"",E22<>F22),"level ","")&IF(AND(L22<>"",M22<>"",L22<>M22),"price ","")&IF(AND(O22<>"",P22<>"",O22<>P22),"xp ","")&IF(J22="differs","time","")),"") | X22: Bell Pepper x3; Bacon x1; Rice x3; Cheese x1 | Y22: Stuffed Peppers.png | Z22: icons/BBQ Grill/Stuffed Peppers.png | AA22: hayday.info /api/production-data (2026-10-13) + Hay Day Wiki infobox via MediaWiki API (2026-10-13) | AB22: https://hayday.fandom.com/wiki/Stuffed_Peppers | AC22: Stuffed peppers
... A25: Fish Skewer | B25: BBQ Grill | C25: Product | D25: =IF(E25<>"",E25,IF(F25<>"",F25,"")) | E25: 96 | F25: 96 | G25: 25 | H25: 30 | I25: 25 | J25: =IF(OR(G25="",AND(H25="",I25="")),"n/a",IF(G25=I25,"mastered",IF(G25=H25,"normal","differs"))) | K25: =IF(L25<>"",L25,IF(M25<>"",M25,"")) | L25: 176 | M25: 176 | N25: =IF(O25<>"",O25,IF(P25<>"",P25,"")) | O25: 21 | P25: 21 | Q25: 65.88 | R25: 49.41 | S25: =IF(Q25="","",IF(Q25<0,"negative profit",IF(Q25>Notes!$B$4,"unusually high - verify",""))) | T25: both | U25: =IF(T25<>"both",T25&" only",IF(V25="","agree","conflict")) | V25: =IF(T25="both",TRIM(IF(AND(E25<>"",F25<>"",E25<>F25),"level ","")&IF(AND(L25<>"",M25<>"",L25<>M25),"price ","")&IF(AND(O25<>"",P25<>"",O25<>P25),"xp ","")&IF(J25="differs","time","")),"") | X25: Fish Fillet x1; Mushroom x3; Ginger x1; Sesame x2 | Y25: Fish Skewer.png | Z25: icons/BBQ Grill/Fish Skewer.png | AA25: hayday.info /api/production-data (2026-10-13) + Hay Day Wiki infobox via MediaWiki API (2026-10-13) | AB25: https://hayday.fandom.com/wiki/Fish_Skewer | AC25: Fish skewer
A26: Grilled Lamb Skewer | B26: BBQ Grill | C26: Product | D26: =IF(E26<>"",E26,IF(F26<>"",F26,"")) | F26: 25 | H26: 20 | I26: 17 | J26: =IF(OR(G26="",AND(H26="",I26="")),"n/a",IF(G26=I26,"mastered",IF(G26=H26,"normal","differs"))) | K26: =IF(L26<>"",L26,IF(M26<>"",M26,"")) | M26: 90 | N26: =IF(O26<>"",O26,IF(P26<>"",P26,"")) | P26: 11 | S26: =IF(Q26="","",IF(Q26<0,"negative profit",IF(Q26>Notes!$B$4,"unusually high - verify",""))) | T26: Fandom | U26: =IF(T26<>"both",T26&" only",IF(V26="","agree","conflict")) | V26: =IF(T26="both",TRIM(IF(AND(E26<>"",F26<>"",E26<>F26),"level ","")&IF(AND(L26<>"",M26<>"",L26<>M26),"price ","")&IF(AND(O26<>"",P26<>"",O26<>P26),"xp ","")&IF(J26="differs","time","")),"") | X26: Lamb Chop x2 | Y26: Grilled Lamb Skewer.png | Z26: icons/BBQ Grill/Grilled Lamb Skewer.png | AA26: Hay Day Wiki infobox via MediaWiki API (2026-10-13) | AB26: https://hayday.fandom.com/wiki/Grilled_Lamb_Skewer
A27: Steamed Mussels | B27: BBQ Grill | C27: Product | D27: =IF(E27<>"",E27,IF(F27<>"",F27,"")) | F27: 27 | H27: 15 | I27: 12 | J27: =IF(OR(G27="",AND(H27="",I27="")),"n/a",IF(G27=I27,"mastered",IF(G27=H27,"normal","differs"))) | K27: =IF(L27<>"",L27,IF(M27<>"",M27,"")) | M27: 284 | N27: =IF(O27<>"",O27,IF(P27<>"",P27,"")) | P27: 34 | S27: =IF(Q27="","",IF(Q27<0,"negative profit",IF(Q27>Notes!$B$4,"unusually high - verify",""))) | T27: Fandom | U27: =IF(T27<>"both",T27&" only",IF(V27="","agree","conflict")) | V27: =IF(T27="both",TRIM(IF(AND(E27<>"",F27<>"",E27<>F27),"level ","")&IF(AND(L27<>"",M27<>"",L27<>M27),"price ","")&IF(AND(O27<>"",P27<>"",O27<>P27),"xp ","")&IF(J27="differs","time","")),"") | X27: Mussel Meat x4; Butter x2 | Y27: Steamed Mussels.png | Z27: icons/BBQ Grill/Steamed Mussels.png | AA27: Hay Day Wiki infobox via MediaWiki API (2026-10-13) | AB27: https://hayday.fandom.com/wiki/Steamed_Mussels
A28: Grilled Mussels | B28: BBQ Grill | C28: Product | D28: =IF(E28<>"",E28,IF(F28<>"",F28,"")) | F28: 32 | H28: 80 | I28: 68 | J28: =IF(OR(G28="",AND(H28="",I28="")),"n/a",IF(G28=I28,"mastered",IF(G28=H28,"normal","differs"))) | K28: =IF(L28<>"",L28,IF(M28<>"",M28,"")) | M28: 370 | N28: =IF(O28<>"",O28,IF(P28<>"",P28,"")) | P28: 44 | S28: =IF(Q28="","",IF(Q28<0,"negative profit",IF(Q28>Notes!$B$4,"unusually high - verify",""))) | T28: Fandom | U28: =IF(T28<>"both",T28&" only",IF(V28="","agree","conflict")) | V28: =IF(T28="both",TRIM(IF(AND(E28<>"",F28<>"",E28<>F28),"level ","")&IF(AND(L28<>"",M28<>"",L28<>M28),"price ","")&IF(AND(O28<>"",P28<>"",O28<>P28),"xp ","")&IF(J28="differs","time","")),"") | X28: Mussel Meat x3; Butter x1; Chili Pepper x3; Corn Bread x1 | Y28: Grilled Mussels.png | Z28: icons/BBQ Grill/Grilled Mussels.png | AA28: Hay Day Wiki infobox via MediaWiki API (2026-10-13) | AB28: https://hayday.fandom.com/wiki/Grilled_Mussels
A29: Grilled Asparagus | B29: BBQ Grill | C29: Product | D29: =IF(E29<>"",E29,IF(F29<>"",F29,"")) | F29: 67 | H29: 75 | I29: 63 | J29: =IF(OR(G29="",AND(H29="",I29="")),"n/a",IF(G29=I29,"mastered",IF(G29=H29,"normal","differs"))) | K29: =IF(L29<>"",L29,IF(M29<>"",M29,"")) | M29: 486 | N29: =IF(O29<>"",O29,IF(P29<>"",P29,"")) | P29: 58 | S29: =IF(Q29="","",IF(Q29<0,"negative profit",IF(Q29>Notes!$B$4,"unusually high - verify",""))) | T29: Fandom | U29: =IF(T29<>"both",T29&" only",IF(V29="","agree","conflict")) | V29: =IF(T29="both",TRIM(IF(AND(E29<>"",F29<>"",E29<>F29),"level ","")&IF(AND(L29<>"",M29<>"",L29<>M29),"price ","")&IF(AND(O29<>"",P29<>"",O29<>P29),"xp ","")&IF(J29="differs","time","")),"") | X29: Asparagus x5; Bacon x3; Lemon x1 | Y29: Grilled Asparagus.png | Z29: icons/BBQ Grill/Grilled Asparagus.png | AA29: Hay Day Wiki infobox via MediaWiki API (2026-10-13) | AB29: https://hayday.fandom.com/wiki/Grilled_Asparagus
A30: Bread | B30: Bakery | C30: Product | D30: =IF(E30<>"",E30,IF(F30<>"",F30,"")) | E30: 2 | F30: 4 | G30: 4 | H30: 5 | I30: 4 | J30: =IF(OR(G30="",AND(H30="",I30="")),"n/a",IF(G30=I30,"mastered",IF(G30=H30,"normal","differs"))) | K30: =IF(L30<>"",L30,IF(M30<>"",M30,"")) | L30: 21 | M30: 21 | N30: =IF(O30<>"",O30,IF(P30<>"",P30,"")) | O30: 3 | P30: 3 | Q30: 169.41 | R30: 42.35 | S30: =IF(Q30="","",IF(Q30<0,"negative profit",IF(Q30>Notes!$B$4,"unusually high - verify",""))) | T30: both | U30: =IF(T30<>"both",T30&" only",IF(V30="","agree","conflict")) | V30: =IF(T30="both",TRIM(IF(AND(E30<>"",F30<>"",E30<>F30),"level ","")&IF(AND(L30<>"",M30<>"",L30<>M30),"price ","")&IF(AND(O30<>"",P30<>"",O30<>P30),"xp ","")&IF(J30="differs","time","")),"") | X30: Wheat x3 | Y30: Bread.png | Z30: icons/Bakery/Bread.png | AA30: hayday.info /api/production-data (2026-10-13) + Hay Day Wiki infobox via MediaWiki API (2026-10-13) | AB30: https://hayday.fandom.com/wiki/Bread | AC30: Bread
A31: Corn Bread | B31: Bakery | C31: Product | D31: =IF(E31<>"",E31,IF(F31<>"",F31,"")) | E31: 7 | F31: 7 | G31: 25 | H31: 30 | I31: 25 | J31: =IF(OR(G31="",AND(H31="",I31="")),"n/a",IF(G31=I31,"mastered",IF(G31=H31,"normal","differs"))) | K31: =IF(L31<>"",L31,IF(M31<>"",M31,"")) | L31: 72 | M31: 72 | N31: =IF(O31<>"",O31,IF(P31<>"",P31,"")) | O31: 8 | P31: 8 | Q31: 51.76 | R31: 18.82 | S31: =IF(Q31="","",IF(Q31<0,"negative profit",IF(Q31>Notes!$B$4,"unusually high - verify",""))) | T31: both | U31: =IF(T31<>"both",T31&" only",IF(V31="","agree","conflict")) | V31: =IF(T31="both",TRIM(IF(AND(E31<>"",F31<>"",E31<>F31),"level ","")&IF(AND(L31<>"",M31<>"",L31<>M31),"price ","")&IF(AND(O31<>"",P31<>"",O31<>P31),"xp ","")&IF(J31="differs","time","")),"") | X31: Corn x2; Egg x2 | Y31: Corn_Bread.png | Z31: icons/Bakery/Corn Bread.png | AA31: hayday.info /api/production-data (2026-10-13) + Hay Day Wiki infobox via MediaWiki API (2026-10-13) | AB31: https://hayday.fandom.com/wiki/Corn_Bread | AC31: Corn bread
A32: Cookie | B32: Bakery | C32: Product | D32: =IF(E32<>"",E32,IF(F32<>"",F32,"")) | E32: 10 | F32: 10 | G32: 51 | H32: 60 | I32: 51 | J32: =IF(OR(G32="",AND(H32="",I32="")),"n/a",IF(G32=I32,"mastered",IF(G32=H32,"normal","differs"))) | K32: =IF(L32<>"",L32,IF(M32<>"",M32,"")) | L32: 104 | M32: 104 | N32: =IF(O32<>"",O32,IF(P32<>"",P32,"")) | O32: 13 | P32: 13 | Q32: 35.29 | R32: 15.29 | S32: =IF(Q32="","",IF(Q32<0,"negative profit",IF(Q32>Notes!$B$4,"unusually high - verify",""))) | T32: both | U32: =IF(T32<>"both",T32&" only",IF(V32="","agree","conflict")) | V32: =IF(T32="both",TRIM(IF(AND(E32<>"",F32<>"",E32<>F32),"level ","")&IF(AND(L32<>"",M32<>"",L32<>M32),"price ","")&IF(AND(O32<>"",P32<>"",O32<>P32),"xp ","")&IF(J32="differs","time","")),"") | X32: Wheat x2; Egg x2; Brown Sugar x1 | Y32: Cookie.png | Z32: icons/Bakery/Cookie.png | AA32: hayday.info /api/production-data (2026-10-13) + Hay Day Wiki infobox via MediaWiki API (2026-10-13) | AB32: https://hayday.fandom.com/wiki/Cookie | AC32: Cookie
A33: Raspberry Muffin | B33: Bakery | C33: Product | D33: =IF(E33<>"",E33,IF(F33<>"",F33,"")) | E33: 19 | F33: 19 | G33: 38 | H33: 45 | I33: 38 | J33: =IF(OR(G33="",AND(H33="",I33="")),"n/a",IF(G33=I33,"mastered",IF(G33=H33,"normal","differs"))) | K33: =IF(L33<>"",L33,IF(M33<>"",M33,"")) | L33: 140 | M33: 140 | N33: =IF(O33<>"",O33,IF(P33<>"",P33,"")) | O33: 17 | P33: 17 | Q33: 37.65 | R33: 26.67 | S33: =IF(Q33="","",IF(Q33<0,"negative profit",IF(Q33>Notes!$B$4,"unusually high - verify",""))) | T33: both | U33: =IF(T33<>"both",T33&" only",IF(V33="","agree","conflict")) | V33: =IF(T33="both",TRIM(IF(AND(E33<>"",F33<>"",E33<>F33),"level ","")&IF(AND(L33<>"",M33<>"",L33<>M33),"price ","")&IF(AND(O33<>"",P33<>"",O33<>P33),"xp ","")&IF(J33="differs","time","")),"") | X33: Wheat x2; Egg x1; Raspberry x2 | Y33: Raspberry_Muffin.png | Z33: icons/Bakery/Raspberry Muffin.png | AA33: hayday.info /api/production-data (2026-10-13) + Hay Day Wiki infobox via MediaWiki API (2026-10-13) | AB33: https://hayday.fandom.com/wiki/Raspberry_Muffin | AC33: Raspberry muffin
A34: Blackberry Muffin | B34: Bakery | C34: Product | D34: =IF(E34<>"",E34,IF(F34<>"",F34,"")) | E34: 26 | F34: 26 | G34: 38 | H34: 45 | I34: 38 | J34: =IF(OR(G34="",AND(H34="",I34="")),"n/a",IF(G34=I34,"mastered",IF(G34=H34,"normal","differs"))) | K34: =IF(L34<>"",L34,IF(M34<>"",M34,"")) | L34: 226 | M34: 226 | N34: =IF(O34<>"",O34,IF(P34<>"",P34,"")) | O34: 27 | P34: 27 | Q34: 36.08 | R34: 42.35 | S34: =IF(Q34="","",IF(Q34<0,"negative profit",IF(Q34>Notes!$B$4,"unusually high - verify",""))) | T34: both | U34: =IF(T34<>"both",T34&" only",IF(V34="","agree","conflict")) | V34: =IF(T34="both",TRIM(IF(AND(E34<>"",F34<>"",E34<>F34),"level ","")&IF(AND(L34<>"",M34<>"",L34<>M34),"price ","")&IF(AND(O34<>"",P34<>"",O34<>P34),"xp ","")&IF(J34="differs","time","")),"") | X34: Wheat x1; Egg x2; Blackberry x2 | Y34: Blackberry_Muffin.png | Z34: icons/Bakery/Blackberry Muffin.png | AA34: hayday.info /api/production-data (2026-10-13) + Hay Day Wiki infobox via MediaWiki API (2026-10-13) | AB34: https://hayday.fandom.com/wiki/Blackberry_Muffin | AC34: Blackberry muffin
A35: Pizza | B35: Bakery | C35: Product | D35: =IF(E35<>"",E35,IF(F35<>"",F35,"")) | E35: 33 | F35: 33 | G35: 12 | H35: 15 | I35: 12 | J35: =IF(OR(G35="",AND(H35="",I35="")),"n/a",IF(G35=I35,"mastered",IF(G35=H35,"normal","differs"))) | K35: =IF(L35<>"",L35,IF(M35<>"",M35,"")) | L35: 190 | M35: 190 | N35: =IF(O35<>"",O35,IF(P35<>"",P35,"")) | O35: 23 | P35: 23 | Q35: 89.41 | R35: 108.24 | S35: =IF(Q35="","",IF(Q35<0,"negative profit",IF(Q35>Notes!$B$4,"unusually high - verify",""))) | T35: both | U35: =IF(T35<>"both",T35&" only",IF(V35="","agree","conflict")) | V35: =IF(T35="both",TRIM(IF(AND(E35<>"",F35<>"",E35<>F35),"level ","")&IF(AND(L35<>"",M35<>"",L35<>M35),"price ","")&IF(AND(O35<>"",P35<>"",O35<>P35),"xp ","")&IF(J35="differs","time","")),"") | X35: Wheat x2; Tomato x1; Cheese x1 | Y35: Pizza.png | Z35: icons/Bakery/Pizza.png | AA35: hayday.info /api/production-data (2026-10-13) + Hay Day Wiki infobox via MediaWiki API (2026-10-13) | AB35: https://hayday.fandom.com/wiki/Pizza | AC35: Pizza
A36: Spicy Pizza | B36: Bakery | C36: Product | D36: =IF(E36<>"",E36,IF(F36<>"",F36,"")) | E36: 37 | F36: 37 | G36: 12 | H36: 15 | I36: 12 | J36: =IF(OR(G36="",AND(H36="",I36="")),"n/a",IF(G36=I36,"mastered",IF(G36=H36,"normal","differs"))) | K36: =IF(L36<>"",L36,IF(M36<>"",M36,"")) | L36: 226 | M36: 226 | N36: =IF(O36<>"",O36,IF(P36<>"",P36,"")) | O36: 27 | P36: 27 | Q36: 89.41 | R36: 127.06 | S36: =IF(Q36="","",IF(Q36<0,"negative profit",IF(Q36>Notes!$B$4,"unusually high - verify",""))) | T36: both | U36: =IF(T36<>"both",T36&" only",IF(V36="","agree","conflict")) | V36: =IF(T36="both",TRIM(IF(AND(E36<>"",F36<>"",E36<>F36),"level ","")&IF(AND(L36<>"",M36<>"",L36<>M36),"price ","")&IF(AND(O36<>"",P36<>"",O36<>P36),"xp ","")&IF(J36="differs","time","")),"") | X36: Wheat x2; Tomato x1; Cheese x1; Chili Pepper x1 | Y36: Spicy Pizza.png | Z36: icons/Bakery/Spicy Pizza.png | AA36: hayday.info /api/production-data (2026-10-13) + Hay Day Wiki infobox via MediaWiki API (2026-10-13) | AB36: https://hayday.fandom.com/wiki/Spicy_Pizza | AC36: Spicy pizza
A37: Potato Bread | B37: Bakery | C37: Product | D37: =IF(E37<>"",E37,IF(F37<>"",F37,"")) | E37: 39 | F37: 39 | G37: 38 | H37: 45 | I37: 38 | J37: =IF(OR(G37="",AND(H37="",I37="")),"n/a",IF(G37=I37,"mastered",IF(G37=H37,"normal","differs"))) | K37: =IF(L37<>"",L37,IF(M37<>"",M37,"")) | L37: 284 | M37: 284 | N37: =IF(O37<>"",O37,IF(P37<>"",P37,"")) | O37: 34 | P37: 34 | Q37: 40.78 | R37: 53.33 | S37: =IF(Q37="","",IF(Q37<0,"negative profit",IF(Q37>Notes!$B$4,"unusually high - verify",""))) | T37: both | U37: =IF(T37<>"both",T37&" only",IF(V37="","agree","conflict")) | V37: =IF(T37="both",TRIM(IF(AND(E37<>"",F37<>"",E37<>F37),"level ","")&IF(AND(L37<>"",M37<>"",L37<>M37),"price ","")&IF(AND(O37<>"",P37<>"",O37<>P37),"xp ","")&IF(J37="differs","time","")),"") | X37: Potato x2; White Sugar x1; Egg x3; Butter x1 | Y37: Potato Bread.png | Z37: icons/Bakery/Potato Bread.png | AA37: hayday.info /api/production-data (2026-10-13) + Hay Day Wiki infobox via MediaWiki API (2026-10-13) | AB37: https://hayday.fandom.com/wiki/Potato_Bread | AC37: Potato bread
A38: Frutti di Mare Pizza | B38: Bakery | C38: Product | D38: =IF(E38<>"",E38,IF(F38<>"",F38,"")) | E38: 45 | F38: 45 | G38: 12 | H38: 15 | I38: 12 | J38: =IF(OR(G38="",AND(H38="",I38="")),"n/a",IF(G38=I38,"mastered",IF(G38=H38,"normal","differs"))) | K38: =IF(L38<>"",L38,IF(M38<>"",M38,"")) | L38: 403 | M38: 403 | N38: =IF(O38<>"",O38,IF(P38<>"",P38,"")) | O38: 48 | P38: 48 | Q38: 94.12 | R38: 225.88 | S38: =IF(Q38="","",IF(Q38<0,"negative profit",IF(Q38>Notes!$B$4,"unusually high - verify",""))) | T38: both | U38: =IF(T38<>"both",T38&" only",IF(V38="","agree","conflict")) | V38: =IF(T38="both",TRIM(IF(AND(E38<>"",F38<>"",E38<>F38),"level ","")&IF(AND(L38<>"",M38<>"",L38<>M38),"price ","")&IF(AND(O38<>"",P38<>"",O38<>P38),"xp ","")&IF(J38="differs","time","")),"") | X38: Wheat x2; Fish Fillet x1; Lobster Tail x1; Cheese x1 | Y38: Frutti_di_Mare_Pizza.png | Z38: icons/Bakery/Frutti di Mare Pizza.png | AA38: hayday.info /api/production-data (2026-10-13) + Hay Day Wiki infobox via MediaWiki API (2026-10-13) | AB38: https://hayday.fandom.com/wiki/Frutti_di_Mare_Pizza | AC38: Frutti di Mare pizza
A39: Gingerbread Cookie | B39: Bakery | C39: Product | D39: =IF(E39<>"",E39,IF(F39<>"",F39,"")) | E39: 86 | F39: 86 | G39: 25 | H39: 30 | I39: 25 | J39: =IF(OR(G39="",AND(H39="",I39="")),"n/a",IF(G39=I39,"mastered",IF(G39=H39,"normal","differs"))) | K39: =IF(L39<>"",L39,IF(M39<>"",M39,"")) | L39: 273 | M39: 273 | N39: =IF(O39<>"",O39,IF(P39<>"",P39,"")) | O39: 33 | P39: 33 | Q39: 70.59 | R39: 77.65 | S39: =IF(Q39="","",IF(Q39<0,"negative profit",IF(Q39>Notes!$B$4,"unusually high - verify",""))) | T39: both | U39: =IF(T39<>"both",T39&" only",IF(V39="","agree","conflict")) | V39: =IF(T39="both",TRIM(IF(AND(E39<>"",F39<>"",E39<>F39),"level ","")&IF(AND(L39<>"",M39<>"",L39<>M39),"price ","")&IF(AND(O39<>"",P39<>"",O39<>P39),"xp ","")&IF(J39="differs","time","")),"") | X39: Wheat x5; Butter x1; Syrup x1; Ginger x2 | Y39: Gingerbread Cookie.png | Z39: icons/Bakery/Gingerbread Cookie.png | AA39: hayday.info /api/production-data (2026-10-13) + Hay Day Wiki infobox via MediaWiki API (2026-10-13) | AB39: https://hayday.fandom.com/wiki/Gingerbread_Cookie | AC39: Gingerbread cookie
A40: Banana Bread | B40: Bakery | C40: Product | D40: =IF(E40<>"",E40,IF(F40<>"",F40,"")) | E40: 91 | F40: 91 | G40: 25 | H40: 30 | I40: 25 | J40: =IF(OR(G40="",AND(H40="",I40="")),"n/a",IF(G40=I40,"mastered",IF(G40=H40,"normal","differs"))) | K40: =IF(L40<>"",L40,IF(M40<>"",M40,"")) | L40: 424 | M40: 424 | N40: =IF(O40<>"",O40,IF(P40<>"",P40,"")) | O40: 50 | P40: 50 | Q40: 49.41 | R40: 117.65 | S40: =IF(Q40="","",IF(Q40<0,"negative profit",IF(Q40>Notes!$B$4,"unusually high - verify",""))) | T40: both | U40: =IF(T40<>"both",T40&" only",IF(V40="","agree","conflict")) | V40: =IF(T40="both",TRIM(IF(AND(E40<>"",F40<>"",E40<>F40),"level ","")&IF(AND(L40<>"",M40<>"",L40<>M40),"price ","")&IF(AND(O40<>"",P40<>"",O40<>P40),"xp ","")&IF(J40="differs","time","")),"") | X40: Banana x3; Grapes x2; Wheat x3; Egg x1 | Y40: Banana Bread.png | Z40: icons/Bakery/Banana Bread.png | AA40: hayday.info /api/production-data (2026-10-13) + Hay Day Wiki infobox via MediaWiki API (2026-10-13) | AB40: https://hayday.fandom.com/wiki/Banana_Bread | AC40: Banana bread
A41: Macaroon | B41: Bakery | C41: Product | D41: =IF(E41<>"",E41,IF(F41<>"",F41,"")) | E41: 101 | F41: 101 | G41: 30 | H41: 30 | I41: 25 | J41: =IF(OR(G41="",AND(H41="",I41="")),"n/a",IF(G41=I41,"mastered",IF(G41=H41,"normal","differs"))) | K41: =IF(L41<>"",L41,IF(M41<>"",M41,"")) | L41: 421 | M41: 421 | N41: =IF(O41<>"",O41,IF(P41<>"",P41,"")) | O41: 50 | P41: 50 | Q41: 38 | R41: 100 | S41: =IF(Q41="","",IF(Q41<0,"negative profit",IF(Q41>Notes!$B$4,"unusually high - verify",""))) | T41: both | U41: =IF(T41<>"both",T41&" only",IF(V41="","agree","conflict")) | V41: =IF(T41="both",TRIM(IF(AND(E41<>"",F41<>"",E41<>F41),"level ","")&IF(AND(L41<>"",M41<>"",L41<>M41),"price ","")&IF(AND(O41<>"",P41<>"",O41<>P41),"xp ","")&IF(J41="differs","time","")),"") | X41: Cacao x1; Coconut x2; White Sugar x2 | Y41: Macaroon.png | Z41: icons/Bakery/Macaroon.png | AA41: hayday.info /api/production-data (2026-10-13) + Hay Day Wiki infobox via MediaWiki API (2026-10-13) | AB41: https://hayday.fandom.com/wiki/Macaroon | AC41: Macaroon
A42: Blueberry Muffin | B42: Bakery | C42: Product | D42: =IF(E42<>"",E42,IF(F42<>"",F42,"")) | F42: 33 | H42: 45 | I42: 38 | J42: =IF(OR(G42="",AND(H42="",I42="")),"n/a",IF(G42=I42,"mastered",IF(G42=H42,"normal","differs"))) | K42: =IF(L42<>"",L42,IF(M42<>"",M42,"")) | M42: 230 | N42: =IF(O42<>"",O42,IF(P42<>"",P42,"")) | P42: 28 | S42: =IF(Q42="","",IF(Q42<0,"negative profit",IF(Q42>Notes!$B$4,"unusually high - verify",""))) | T42: Fandom | U42: =IF(T42<>"both",T42&" only",IF(V42="","agree","conflict")) | V42: =IF(T42="both",TRIM(IF(AND(E42<>"",F42<>"",E42<>F42),"level ","")&IF(AND(L42<>"",M42<>"",L42<>M42),"price ","")&IF(AND(O42<>"",P42<>"",O42<>P42),"xp ","")&IF(J42="differs","time","")),"") | X42: Wheat x1; Egg x2; Blueberries x2 | Y42: Blueberry_Muffin.png | Z42: icons/Bakery/Blueberry Muffin.png | AA42: Hay Day Wiki infobox via MediaWiki API (2026-10-13) | AB42: https://hayday.fandom.com/wiki/Blueberry_Muffin
...

Sheet chain_economics
A1: Product | B1: Type | C1: Machine / source | D1: Level | E1: Price | F1: Price source | G1: Yield per batch | H1: Own time (min) | I1: Own time mastered (min) | J1: Ingredient value (coins) | K1: Machine-min | L1: Field-min | M1: Animal-min | N1: Tree-min | O1: External inputs (time not modelled) | P1: Total chain min | Q1: Critical path min | R1: Coins/hr per chain-min | S1: Machine-min mastered | T1: Total chain min mastered | U1: Critical path min mastered | V1: Coins/hr per chain-min mastered | W1: Value added (coins) | X1: Value added/hr own machine | Y1: Value added/hr own machine mastered | Z1: hayday.info profit/hr | AA1: Ingredients | AB1: Unlocked at L39 (whole chain) | AC1: Check vs hayday.info
A2: Honey Peanuts | B2: machine | C2: Candy Machine | D2: 63 | E2: 540 | F2: hayday.info | G2: 1 | H2: 40 | I2: 34 | J2: 388 | K2: 60 | L2: 0 | M2: 70 | N2: 0 | O2: Peanuts x1 | P2: 130 | Q2: 95 | R2: 249.23 | S2: 51 | T2: 121 | U2: 86 | V2: 267.77 | W2: 152 | X2: 228 | Y2: 268.24 | Z2: 268.24 | AA2: Honey x1; Peanuts x1 | AB2: FALSE | AC2: match (mastered)
A3: Snack Mix | B3: machine | C3: Popcorn Pot | D3: 64 | E3: 309 | F3: hayday.info | G3: 1 | H3: 45 | I3: 38 | J3: 266 | K3: 45 | L3: 70 | M3: 0 | N3: 0 | O3: Peanuts x1 | P3: 115 | Q3: 105 | R3: 161.22 | S3: 38 | T3: 108 | U3: 98 | V3: 171.67 | W3: 43 | X3: 57.33 | Y3: 67.89 | Z3: 67.45 | AA3: Corn x2; Sesame x1; Peanuts x1 | AB3: FALSE | AC3: match (mastered)
A4: Honeycomb | B4: animal | C4: Honey Bee | D4: 39 | E4: 68 | F4: hayday.info | G4: 1 | H4: 35 | J4: 0 | K4: 0 | L4: 0 | M4: 35 | N4: 0 | P4: 35 | Q4: 35 | R4: 116.57 | S4: 0 | T4: 35 | U4: 35 | V4: 116.57 | W4: 68 | X4: 116.57 | Y4: 116.57 | Z4: 109.71 | AB4: TRUE
A5: Bread | B5: machine | C5: Bakery | D5: 4 | E5: 21 | F5: hayday.info | G5: 1 | H5: 5 | I5: 4 | J5: 9 | K5: 5 | L5: 6 | M5: 0 | N5: 0 | P5: 11 | Q5: 7 | R5: 114.55 | S5: 4 | T5: 10 | U5: 6 | V5: 126 | W5: 12 | X5: 144 | Y5: 180 | Z5: 169.41 | AA5: Wheat x3 | AB5: TRUE | AC5: match (normal x0.85)
A6: Honey | B6: machine | C6: Honey Extractor | D6: 39 | E6: 154 | F6: hayday.info | G6: 1 | H6: 20 | I6: 17 | J6: 136 | K6: 20 | L6: 0 | M6: 70 | N6: 0 | P6: 90 | Q6: 55 | R6: 102.67 | S6: 17 | T6: 87 | U6: 52 | V6: 106.21 | W6: 18 | X6: 54 | Y6: 63.53 | Z6: 63.53 | AA6: Honeycomb x2 | AB6: TRUE | AC6: match (mastered)
A7: Beeswax | B7: machine | C7: Honey Extractor | D7: 48 | E7: 234 | F7: hayday.info | G7: 1 | H7: 45 | I7: 38 | J7: 204 | K7: 45 | L7: 0 | M7: 105 | N7: 0 | P7: 150 | Q7: 80 | R7: 93.6 | S7: 38 | T7: 143 | U7: 73 | V7: 98.18 | W7: 30 | X7: 40 | Y7: 47.37 | Z7: 47.06 | AA7: Honeycomb x3 | AB7: FALSE | AC7: match (mastered)
A8: Fish Pie | B8: machine | C8: Pie Oven | D8: 28 | E8: 226 | F8: hayday.info | G8: 1 | H8: 120 | I8: 102 | J8: 186 | K8: 121.67 | L8: 7 | M8: 20 | N8: 0 | O8: Fish Fillet x3 | P8: 148.67 | Q8: 150 | R8: 91.21 | S8: 103.33 | T8: 130.33 | U8: 131 | V8: 104.04 | W8: 40 | X8: 20 | Y8: 23.53 | Z8: 23.53 | AA8: Fish Fillet x3; Wheat x2; Egg x1 | AB8: TRUE | AC8: match (mastered)
A9: Wheat | B9: field | C9: Farm | D9: 1 | E9: 3 | F9: hayday.info | G9: 1 | H9: 2 | J9: 0 | K9: 0 | L9: 2 | M9: 0 | N9: 0 | P9: 2 | Q9: 2 | R9: 90 | S9: 0 | T9: 2 | U9: 2 | V9: 90 | W9: 3 | X9: 90 | Y9: 90 | Z9: 90 | AB9: TRUE
A10: Chicken Feed | B10: machine | C10: Feed Mill | D10: 2 | E10: 7 | F10: hayday.info | G10: 3 | H10: 5 | I10: 4 | J10: 4.33 | K10: 1.67 | L10: 3 | M10: 0 | N10: 0 | P10: 4.67 | Q10: 10 | R10: 90 | S10: 1.33 | T10: 4.33 | U10: 9 | V10: 96.92 | W10: 2.67 | X10: 96 | Y10: 120 | Z10: 112.94 | AA10: Wheat x2; Corn x1 | AB10: TRUE | AC10: match (normal x0.85)
A11: Corn | B11: field | C11: Farm | D11: 2 | E11: 7 | F11: hayday.info | G11: 1 | H11: 5 | J11: 0 | K11: 0 | L11: 5 | M11: 0 | N11: 0 | P11: 5 | Q11: 5 | R11: 84 | S11: 0 | T11: 5 | U11: 5 | V11: 84 | W11: 7 | X11: 84 | Y11: 84 | Z11: 84 | AB11: TRUE
A12: Honey Popcorn | B12: machine | C12: Popcorn Pot | D12: 40 | E12: 360 | F12: hayday.info | G12: 1 | H12: 90 | I12: 76 | J12: 322 | K12: 130 | L12: 10 | M12: 140 | N12: 0 | P12: 280 | Q12: 165 | R12: 77.14 | S12: 110 | T12: 260 | U12: 145 | V12: 83.08 | W12: 38 | X12: 25.33 | Y12: 30 | Z12: 29.8 | AA12: Corn x2; Honey x2 | AB12: FALSE | AC12: match (mastered)
A13: Frutti di Mare Pizza | B13: machine | C13: Bakery | D13: 45 | E13: 403 | F13: hayday.info | G13: 1 | H13: 15 | I13: 12 | J13: 383 | K13: 85 | L13: 49 | M13: 180 | N13: 0 | O13: Fish Fillet x1; Lobster Tail x1 | P13: 314 | Q13: 165 | R13: 77.01 | S13: 71 | T13: 300 | U13: 151 | V13: 80.6 | W13: 20 | X13: 80 | Y13: 100 | Z13: 94.12 | AA13: Wheat x2; Fish Fillet x1; Lobster Tail x1; Cheese x1 | AB13: FALSE | AC13: match (normal x0.85)
A14: Lobster Skewer | B14: machine | C14: BBQ Grill | D14: 48 | E14: 417 | F14: hayday.info | G14: 1 | H14: 40 | I14: 34 | J14: 391 | K14: 60 | L14: 240 | M14: 70 | N14: 0 | O14: Lobster Tail x1 | P14: 370 | Q14: 280 | R14: 67.62 | S14: 51 | T14: 361 | U14: 274 | V14: 69.31 | W14: 26 | X14: 39 | Y14: 45.88 | Z14: 45.88 | AA14: Lobster Tail x1; Chili Pepper x1; Honey x1 | AB14: FALSE | AC14: match (mastered)
A15: Oats | B15: field | C15: Farm | D15: 119 | E15: 7 | F15: Fandom | G15: 1 | H15: 7 | J15: 0 | K15: 0 | L15: 7 | M15: 0 | N15: 0 | P15: 7 | Q15: 7 | R15: 60 | S15: 0 | T15: 7 | U15: 7 | V15: 60 | W15: 7 | X15: 60 | Y15: 60 | AB15: FALSE
A16: Fresh Pasta | B16: machine | C16: Pasta Maker | D16: 67 | E16: 43 | F16: hayday.info | G16: 1 | H16: 15 | I16: 12 | J16: 24 | K16: 16.67 | L16: 7 | M16: 20 | N16: 0 | P16: 43.67 | Q16: 45 | R16: 59.08 | S16: 13.33 | T16: 40.33 | U16: 41 | V16: 63.97 | W16: 19 | X16: 76 | Y16: 95 | Z16: 89.41 | AA16: Egg x1; Wheat x2 | AB16: FALSE | AC16: match (normal x0.85)
A17: Honey Toast | B17: machine | C17: Sandwich Bar | D17: 69 | E17: 255 | F17: hayday.info | G17: 1 | H17: 60 | I17: 51 | J17: 225 | K17: 90 | L17: 24 | M17: 150 | N17: 0 | P17: 264 | Q17: 150 | R17: 57.95 | S17: 76 | T17: 250 | U17: 139 | V17: 61.2 | W17: 30 | X17: 30 | Y17: 35.29 | Z17: 35.29 | AA17: Bread x1; Egg x1; Milk x1; Honey x1 | AB17: FALSE | AC17: match (mastered)
A18: Chamomile Tea | B18: machine | C18: Tea Stand | D18: 100 | E18: 144 | F18: Fandom | G18: 1 | H18: 20 | I18: 17 | J18: 118 | K18: 20 | L18: 100 | M18: 35 | N18: 0 | P18: 155 | Q18: 55 | R18: 55.74 | S18: 17 | T18: 152 | U18: 52 | V18: 56.84 | W18: 26 | X18: 78 | Y18: 91.76 | AA18: Chamomile x5; Honeycomb x1 | AB18: FALSE
A19: Peanut Noodles | B19: machine | C19: Wok Kitchen | D19: 86 | E19: 669 | F19: hayday.info | G19: 1 | H19: 45 | I19: 38 | J19: 516 | K19: 245 | L19: 557 | M19: 0 | N19: 0 | O19: Peanuts x1 | P19: 802 | Q19: 245 | R19: 50.05 | S19: 208 | T19: 765 | U19: 211 | V19: 52.47 | W19: 153 | X19: 204 | Y19: 241.58 | Z19: 240 | AA19: Ginger x1; Rice Noodles x1; Soy Sauce x1; Peanuts x1 | AB19: FALSE | AC19: match (normal x0.85)
A20: Cucumber Smoothie | B20: machine | C20: Smoothie Mixer | D20: 70 | E20: 266 | F20: hayday.info | G20: 1 | H20: 40 | I20: 34 | J20: 238 | K20: 60 | L20: 195 | M20: 70 | N20: 0 | P20: 325 | Q20: 95 | R20: 49.11 | S20: 51 | T20: 316 | U20: 86 | V20: 50.51 | W20: 28 | X20: 42 | Y20: 49.41 | Z20: 49.41 | AA20: Cucumber x3; Honey x1; Pineapple x3 | AB20: FALSE | AC20: match (mastered)
A21: Corn Bread | B21: machine | C21: Bakery | D21: 7 | E21: 72 | F21: hayday.info | G21: 1 | H21: 30 | I21: 25 | J21: 50 | K21: 33.33 | L21: 16 | M21: 40 | N21: 0 | P21: 89.33 | Q21: 60 | R21: 48.36 | S21: 27.67 | T21: 83.67 | U21: 54 | V21: 51.63 | W21: 22 | X21: 44 | Y21: 52.8 | Z21: 51.76 | AA21: Corn x2; Egg x2 | AB21: TRUE | AC21: match (normal x0.85)
A22: Popcorn | B22: machine | C22: Popcorn Pot | D22: 8 | E22: 32 | F22: hayday.info | G22: 1 | H22: 30 | I22: 25 | J22: 14 | K22: 30 | L22: 10 | M22: 0 | N22: 0 | P22: 40 | Q22: 35 | R22: 48 | S22: 25 | T22: 35 | U22: 30 | V22: 54.86 | W22: 18 | X22: 36 | Y22: 43.2 | Z22: 42.35 | AA22: Corn x2 | AB22: TRUE | AC22: match (normal x0.85)
A23: Carrot Juice | B23: machine | C23: Juice Press | D23: 26 | E23: 46 | F23: hayday.info | G23: 1 | H23: 30 | I23: 25 | J23: 21 | K23: 30 | L23: 30 | M23: 0 | N23: 0 | P23: 60 | Q23: 40 | R23: 46 | S23: 25 | T23: 55 | U23: 35 | V23: 50.18 | W23: 25 | X23: 50 | Y23: 60 | Z23: 58.82 | AA23: Carrot x3 | AB23: TRUE | AC23: match (normal x0.85)
A24: Cow Feed | B24: machine | C24: Feed Mill | D24: 6 | E24: 14 | F24: hayday.info | G24: 3 | H24: 10 | I24: 8 | J24: 9 | K24: 3.33 | L24: 15 | M24: 0 | N24: 0 | P24: 18.33 | Q24: 30 | R24: 45.82 | S24: 2.67 | T24: 17.67 | U24: 28 | V24: 47.55 | W24: 5 | X24: 90 | Y24: 112.5 | Z24: 105.88 | AA24: Soybean x2; Corn x1 | AB24: TRUE | AC24: match (normal x0.85)
A25: Meat Bucket | B25: machine | C25: Feed Mill | E25: 72 | F25: hayday.info | G25: 1 | H25: 45 | I25: 38 | J25: 197 | K25: 45 | L25: 50 | M25: 0 | N25: 0 | O25: Fish Fillet x3 | P25: 95 | Q25: 55 | R25: 45.47 | S25: 38 | T25: 88 | U25: 48 | V25: 49.09 | W25: -125 | X25: -166.67 | Y25: -197.37 | Z25: 29.8 | AA25: Fish Fillet x3; Carrot x5 | AB25: FALSE | AC25: differs - check recipe / ingredient prices
A26: Sheep Feed | B26: machine | C26: Feed Mill | D26: 16 | E26: 14 | F26: hayday.info | G26: 3 | H26: 30 | I26: 25 | J26: 6.33 | K26: 10 | L26: 8.67 | M26: 0 | N26: 0 | P26: 18.67 | Q26: 50 | R26: 45 | S26: 8.33 | T26: 17 | U26: 45 | V26: 49.41 | W26: 7.67 | X26: 46 | Y26: 55.2 | Z26: 54.12 | AA26: Wheat x3; Soybean x1 | AB26: TRUE | AC26: match (normal x0.85)
A27: Steamed Mussels | B27: machine | C27: BBQ Grill | D27: 27 | E27: 284 | F27: Fandom | G27: 1 | H27: 15 | I27: 12 | J27: 276 | K27: 88.33 | L27: 60 | M27: 240 | N27: 0 | O27: Mussel Meat x4 | P27: 388.33 | Q27: 175 | R27: 43.88 | S27: 72.67 | T27: 372.67 | U27: 158 | V27: 45.72 | W27: 8 | X27: 32 | Y27: 40 | AA27: Mussel Meat x4; Butter x2 | AB27: TRUE
A28: Egg | B28: animal | C28: Chicken | D28: 1 | E28: 18 | F28: hayday.info | G28: 1 | H28: 20 | J28: 7 | K28: 1.67 | L28: 3 | M28: 20 | N28: 0 | P28: 24.67 | Q28: 30 | R28: 43.78 | S28: 1.33 | T28: 24.33 | U28: 29 | V28: 44.38 | W28: 11 | X28: 33 | Y28: 33 | Z28: 33 | AA28: Chicken Feed x1 | AB28: TRUE
A29: Pancake | B29: machine | C29: BBQ Grill | D29: 9 | E29: 108 | F29: hayday.info | G29: 1 | H29: 30 | I29: 25 | J29: 86 | K29: 55 | L29: 39 | M29: 60 | N29: 0 | P29: 154 | Q29: 80 | R29: 42.08 | S29: 46 | T29: 145 | U29: 72 | V29: 44.69 | W29: 22 | X29: 44 | Y29: 52.8 | Z29: 51.76 | AA29: Egg x3; Brown Sugar x1 | AB29: TRUE | AC29: match (normal x0.85)
A30: Carrot | B30: field | C30: Farm | D30: 9 | E30: 7 | F30: hayday.info | G30: 1 | H30: 10 | J30: 0 | K30: 0 | L30: 10 | M30: 0 | N30: 0 | P30: 10 | Q30: 10 | R30: 42 | S30: 0 | T30: 10 | U30: 10 | V30: 42 | W30: 7 | X30: 42 | Y30: 42 | Z30: 42 | AB30: TRUE
A31: Black Bean | B31: field | C31: Farm | D31: 25 | E31: 7 | F31: Fandom | G31: 1 | H31: 10 | J31: 0 | K31: 0 | L31: 10 | M31: 0 | N31: 0 | P31: 10 | Q31: 10 | R31: 42 | S31: 0 | T31: 10 | U31: 10 | V31: 42 | W31: 7 | X31: 42 | Y31: 42 | AB31: TRUE
A32: Pig Feed | B32: machine | C32: Feed Mill | D32: 10 | E32: 14 | F32: hayday.info | G32: 3 | H32: 20 | I32: 17 | J32: 8 | K32: 6.67 | L32: 13.33 | M32: 0 | N32: 0 | P32: 20 | Q32: 40 | R32: 42 | S32: 5.67 | T32: 19 | U32: 37 | V32: 44.21 | W32: 6 | X32: 54 | Y32: 63.53 | Z32: 63.53 | AA32: Carrot x2; Soybean x1 | AB32: TRUE | AC32: match (mastered)
A33: Carrot Pie | B33: machine | C33: Pie Oven | D33: 14 | E33: 82 | F33: hayday.info | G33: 1 | H33: 60 | I33: 51 | J33: 45 | K33: 61.67 | L33: 37 | M33: 20 | N33: 0 | P33: 118.67 | Q33: 90 | R33: 41.46 | S33: 52.33 | T33: 109.33 | U33: 80 | V33: 45 | W33: 37 | X33: 37 | Y33: 43.53 | Z33: 43.53 | AA33: Carrot x3; Wheat x2; Egg x1 | AB33: TRUE | AC33: match (mastered)
A34: Grilled Lamb Skewer | B34: machine | C34: BBQ Grill | D34: 25 | E34: 90 | F34: Fandom | G34: 1 | H34: 20 | I34: 17 | J34: 72 | K34: 26.67 | L34: 53.33 | M34: 60 | N34: 0 | P34: 140 | Q34: 80 | R34: 38.57 | S34: 22.33 | T34: 135.67 | U34: 75 | V34: 39.8 | W34: 18 | X34: 54 | Y34: 63.53 | AA34: Lamb Chop x2 | AB34: TRUE
A35: Brown Sugar | B35: machine | C35: Sugar Mill | D35: 7 | E35: 32 | F35: hayday.info | G35: 1 | H35: 20 | I35: 17 | J35: 14 | K35: 20 | L35: 30 | M35: 0 | N35: 0 | P35: 50 | Q35: 50 | R35: 38.4 | S35: 17 | T35: 47 | U35: 47 | V35: 40.85 | W35: 18 | X35: 54 | Y35: 63.53 | Z35: 63.53 | AA35: Sugarcane x1 | AB35: TRUE | AC35: match (mastered)
A36: Cookie | B36: machine | C36: Bakery | D36: 10 | E36: 104 | F36: hayday.info | G36: 1 | H36: 60 | I36: 51 | J36: 74 | K36: 83.33 | L36: 40 | M36: 40 | N36: 0 | P36: 163.33 | Q36: 110 | R36: 38.2 | S36: 70.67 | T36: 150.67 | U36: 98 | V36: 41.42 | W36: 30 | X36: 30 | Y36: 35.29 | Z36: 35.29 | AA36: Wheat x2; Egg x2; Brown Sugar x1 | AB36: TRUE | AC36: match (mastered)
A37: Goat Feed | B37: machine | C37: Feed Mill | D37: 32 | E37: 14 | F37: hayday.info | G37: 3 | H37: 40 | I37: 34 | J37: 8 | K37: 13.33 | L37: 9 | M37: 0 | N37: 0 | P37: 22.33 | Q37: 50 | R37: 37.61 | S37: 11.33 | T37: 20.33 | U37: 44 | V37: 41.31 | W37: 6 | X37: 27 | Y37: 31.76 | Z37: 31.76 | AA37: Wheat x1; Corn x1; Carrot x2 | AB37: TRUE | AC37: match (mastered)
A38: Crunchy Donut | B38: machine | C38: Donut Maker | D38: 82 | E38: 594 | F38: hayday.info | G38: 1 | H38: 30 | I38: 25 | J38: 449 | K38: 90 | L38: 84 | M38: 80 | N38: 700 | O38: Peanuts x1 | P38: 954 | Q38: 2130 | R38: 37.36 | S38: 75 | T38: 939 | U38: 2125 | V38: 37.96 | W38: 145 | X38: 290 | Y38: 348 | Z38: 341.18 | AA38: Plain Donut x1; Cacao x1; Peanuts x1 | AB38: FALSE | AC38: match (normal x0.85)
A39: Lamb Chop | B39: animal | C39: Lamb | D39: 25 | E39: 36 | F39: Fandom | G39: 1 | H39: 30 | J39: 18 | K39: 3.33 | L39: 26.67 | M39: 30 | N39: 0 | P39: 60 | Q39: 60 | R39: 36 | S39: 2.67 | T39: 59.33 | U39: 58 | V39: 36.4 | W39: 18 | X39: 36 | Y39: 36 | AA39: Lamb Feed x1 | AB39: TRUE
A40: Blanket | B40: machine | C40: Sewing Machine | D40: 59 | E40: 1098 | F40: hayday.info | G40: 1 | H40: 210 | I40: 178 | J40: 1056 | K40: 300 | L40: 1530 | M40: 0 | N40: 0 | O40: Duck Feather x5 | P40: 1830 | Q40: 450 | R40: 36 | S40: 253 | T40: 1783 | U40: 403 | V40: 36.95 | W40: 42 | X40: 12 | Y40: 14.16 | Z40: 14.12 | AA40: Cotton Fabric x3; Pumpkin x1; Duck Feather x5 | AB40: FALSE | AC40: match (mastered)
...

Sheet merged_clean
A1: Product | B1: Machine | C1: Level | D1: Time normal (min) | E1: Time mastered (min) | F1: Time in hayday.info (min) | G1: hayday.info time basis | H1: Sell price | I1: Sell price (Fandom, if different) | J1: XP | K1: XP (Fandom, if different) | L1: Profit/hr (site) | M1: XP/hr (site) | N1: Flag | O1: Found in | P1: Status | Q1: Conflict fields | R1: Source | S1: Fandom page
A2: Egg | B2: Animal Products | C2: 1 | F2: 20 | G2: =IF(OR(F2="",AND(D2="",E2="")),"n/a",IF(F2=E2,"mastered",IF(F2=D2,"normal","differs"))) | H2: 18 | J2: 2 | L2: 33 | M2: 6 | N2: =IF(L2="","",IF(L2<0,"negative profit",IF(L2>Notes!$B$4,"unusually high - verify",""))) | O2: hayday.info | P2: =IF(O2<>"both",O2&" only",IF(Q2="","agree","conflict")) | Q2: =IF(O2="both",TRIM(IF(I2<>"","price ","")&IF(K2<>"","xp ","")&IF(G2="differs","time","")),"") | R2: hayday.info /api/production-data only
A3: Milk | B3: Animal Products | C3: 6 | F3: 60 | G3: =IF(OR(F3="",AND(D3="",E3="")),"n/a",IF(F3=E3,"mastered",IF(F3=D3,"normal","differs"))) | H3: 32 | J3: 3 | L3: 18 | M3: 3 | N3: =IF(L3="","",IF(L3<0,"negative profit",IF(L3>Notes!$B$4,"unusually high - verify",""))) | O3: hayday.info | P3: =IF(O3<>"both",O3&" only",IF(Q3="","agree","conflict")) | Q3: =IF(O3="both",TRIM(IF(I3<>"","price ","")&IF(K3<>"","xp ","")&IF(G3="differs","time","")),"") | R3: hayday.info /api/production-data only
A4: Bacon | B4: Animal Products | C4: 10 | F4: 240 | G4: =IF(OR(F4="",AND(D4="",E4="")),"n/a",IF(F4=E4,"mastered",IF(F4=D4,"normal","differs"))) | H4: 50 | J4: 5 | L4: -2.5 | M4: 1.25 | N4: =IF(L4="","",IF(L4<0,"negative profit",IF(L4>Notes!$B$4,"unusually high - verify",""))) | O4: hayday.info | P4: =IF(O4<>"both",O4&" only",IF(Q4="","agree","conflict")) | Q4: =IF(O4="both",TRIM(IF(I4<>"","price ","")&IF(K4<>"","xp ","")&IF(G4="differs","time","")),"") | R4: hayday.info /api/production-data only
A5: Wool | B5: Animal Products | C5: 16 | F5: 360 | G5: =IF(OR(F5="",AND(D5="",E5="")),"n/a",IF(F5=E5,"mastered",IF(F5=D5,"normal","differs"))) | H5: 54 | J5: 5 | L5: -0.83333333 | M5: 0.83333333 | N5: =IF(L5="","",IF(L5<0,"negative profit",IF(L5>Notes!$B$4,"unusually high - verify",""))) | O5: hayday.info | P5: =IF(O5<>"both",O5&" only",IF(Q5="","agree","conflict")) | Q5: =IF(O5="both",TRIM(IF(I5<>"","price ","")&IF(K5<>"","xp ","")&IF(G5="differs","time","")),"") | R5: hayday.info /api/production-data only
A6: Goat Milk | B6: Animal Products | C6: 32 | F6: 480 | G6: =IF(OR(F6="",AND(D6="",E6="")),"n/a",IF(F6=E6,"mastered",IF(F6=D6,"normal","differs"))) | H6: 64 | J6: 6 | L6: -1.25 | M6: 0.75 | N6: =IF(L6="","",IF(L6<0,"negative profit",IF(L6>Notes!$B$4,"unusually high - verify",""))) | O6: hayday.info | P6: =IF(O6<>"both",O6&" only",IF(Q6="","agree","conflict")) | Q6: =IF(O6="both",TRIM(IF(I6<>"","price ","")&IF(K6<>"","xp ","")&IF(G6="differs","time","")),"") | R6: hayday.info /api/production-data only
A7: Bread | B7: Bakery | C7: 2 | D7: 5 | E7: 4 | F7: 4 | G7: =IF(OR(F7="",AND(D7="",E7="")),"n/a",IF(F7=E7,"mastered",IF(F7=D7,"normal","differs"))) | H7: 21 | J7: 3 | L7: 169.41176 | M7: 42.352941 | N7: =IF(L7="","",IF(L7<0,"negative profit",IF(L7>Notes!$B$4,"unusually high - verify",""))) | O7: both | P7: =IF(O7<>"both",O7&" only",IF(Q7="","agree","conflict")) | Q7: =IF(O7="both",TRIM(IF(I7<>"","price ","")&IF(K7<>"","xp ","")&IF(G7="differs","time","")),"") | R7: hayday.info (primary values) + Fandom (times, cross-check) | S7: https://hayday.fandom.com/wiki/Bakery
A8: Corn Bread | B8: Bakery | C8: 7 | D8: 30 | E8: 25 | F8: 25 | G8: =IF(OR(F8="",AND(D8="",E8="")),"n/a",IF(F8=E8,"mastered",IF(F8=D8,"normal","differs"))) | H8: 72 | J8: 8 | L8: 51.764706 | M8: 18.823529 | N8: =IF(L8="","",IF(L8<0,"negative profit",IF(L8>Notes!$B$4,"unusually high - verify",""))) | O8: both | P8: =IF(O8<>"both",O8&" only",IF(Q8="","agree","conflict")) | Q8: =IF(O8="both",TRIM(IF(I8<>"","price ","")&IF(K8<>"","xp ","")&IF(G8="differs","time","")),"") | R8: hayday.info (primary values) + Fandom (times, cross-check) | S8: https://hayday.fandom.com/wiki/Bakery
A9: Cookie | B9: Bakery | C9: 10 | D9: 60 | E9: 51 | F9: 51 | G9: =IF(OR(F9="",AND(D9="",E9="")),"n/a",IF(F9=E9,"mastered",IF(F9=D9,"normal","differs"))) | H9: 104 | J9: 13 | L9: 35.294118 | M9: 15.294118 | N9: =IF(L9="","",IF(L9<0,"negative profit",IF(L9>Notes!$B$4,"unusually high - verify",""))) | O9: both | P9: =IF(O9<>"both",O9&" only",IF(Q9="","agree","conflict")) | Q9: =IF(O9="both",TRIM(IF(I9<>"","price ","")&IF(K9<>"","xp ","")&IF(G9="differs","time","")),"") | R9: hayday.info (primary values) + Fandom (times, cross-check) | S9: https://hayday.fandom.com/wiki/Bakery
A10: Raspberry Muffin | B10: Bakery | C10: 19 | D10: 45 | E10: 38 | F10: 38 | G10: =IF(OR(F10="",AND(D10="",E10="")),"n/a",IF(F10=E10,"mastered",IF(F10=D10,"normal","differs"))) | H10: 140 | J10: 17 | L10: 37.647059 | M10: 26.666667 | N10: =IF(L10="","",IF(L10<0,"negative profit",IF(L10>Notes!$B$4,"unusually high - verify",""))) | O10: both | P10: =IF(O10<>"both",O10&" only",IF(Q10="","agree","conflict")) | Q10: =IF(O10="both",TRIM(IF(I10<>"","price ","")&IF(K10<>"","xp ","")&IF(G10="differs","time","")),"") | R10: hayday.info (primary values) + Fandom (times, cross-check) | S10: https://hayday.fandom.com/wiki/Bakery
A11: Blackberry Muffin | B11: Bakery | C11: 26 | D11: 45 | E11: 38 | F11: 38 | G11: =IF(OR(F11="",AND(D11="",E11="")),"n/a",IF(F11=E11,"mastered",IF(F11=D11,"normal","differs"))) | H11: 226 | J11: 27 | L11: 36.078431 | M11: 42.352941 | N11: =IF(L11="","",IF(L11<0,"negative profit",IF(L11>Notes!$B$4,"unusually high - verify",""))) | O11: both | P11: =IF(O11<>"both",O11&" only",IF(Q11="","agree","conflict")) | Q11: =IF(O11="both",TRIM(IF(I11<>"","price ","")&IF(K11<>"","xp ","")&IF(G11="differs","time","")),"") | R11: hayday.info (primary values) + Fandom (times, cross-check) | S11: https://hayday.fandom.com/wiki/Bakery
